Workbook
Name \A: [1]A!#REF!
Name \A: [1]A!#REF!
Name \A: [1]A!#REF!
Name \A: [1]A!#REF!
Name \A: [1]A!#REF!
Name \A: [1]A!#REF!
Name \A: [1]A!#REF!
Name \A: [1]A!#REF!
Name \A: [1]A!#REF!
Name \A: [1]A!#REF!
Name \A: [1]A!#REF!
Name \A: [1]A!#REF!
Name \A: [1]A!#REF!
Name \A: [1]A!#REF!
Name \A: [1]A!#REF!
Name \A: [1]A!#REF!
Name \A: [1]A!#REF!
Name \A: [1]A!#REF!
Name \A: [1]A!#REF!
Name \A: [1]A!#REF!
Name \A: [1]A!#REF!
Name \A: [1]A!#REF!
Name \A: [1]A!#REF!
Name \A: [1]A!#REF!
Name \A: [1]A!#REF!
Name \A: [1]A!#REF!
Name \A: [1]A!#REF!
Name \A: [1]A!#REF!
Name \A: [1]A!#REF!
Name \A: [1]A!#REF!
Name \A: [1]A!#REF!
Name \A: [1]A!#REF!
Name \A: [1]A!#REF!
Name \A: [1]A!#REF!
Name \A: [1]A!#REF!
Name \A: [1]A!#REF!
Name \A: [1]A!#REF!
Name \A: [1]A!#REF!
Name \A: [1]A!#REF!
Name \A: [1]A!#REF!
Name \A: [1]A!#REF!
Name \A: [1]A!#REF!
Name \A: [1]A!#REF!
Name \A: [1]A!#REF!
Name \A: [1]A!#REF!
Name \A: [1]A!#REF!
Name \A: [1]A!#REF!
Name \A: [1]A!#REF!
Name \A: [1]A!#REF!
Name \A: [1]A!#REF!
Name \A: [1]A!#REF!
Name \A: [1]A!#REF!
Name \A: [1]A!#REF!
Name \A: [1]A!#REF!
Name \A: [1]A!#REF!
Name \i: [2]單價2!#REF!
Name \i: [2]單價2!#REF!
Name \i: [2]單價2!#REF!
Name \i: [2]單價2!#REF!
Name \i: [2]單價2!#REF!

Sheet 材料設備送審管制總表202112
A1: 國道高速公路後續路段橋梁耐震補強工程(區段2-1)第M38A2標-烏山頭新化段 材料設備送審管制總表
A2: 項次 | B2: 契約詳細表項次 | C2: 契約數量 | E2: 是否取樣試驗 | F2: 預訂送審日期 | G2: 是否驗廠 | H2: 送審資料(P) | M2: 審查日期 | N2: 備註 (歸檔編號)
H3: 協力廠商資料 | I3: 型錄 | J3: 相關試驗報告 | K3: 樣品 | L3: 其他
B4: 材料(設備)名稱 | F4: 實際送審日期 | G4: 驗廠日期 | M4: 審查結果
A6: 1 | B6: 壹、一、1 結構工程 9 | C6: =1412+116 -> 1528 | D6: M3 | E6: 是 | F6: 109/07/20 | G6: 是 | H6: P | J6: P | M6: 109/07/28(贊洲) 109/08/14(竑榮官田) 109/08/14(竑榮安定) | N6: 贊洲:109.07.28棪嘉南(A2)監字第10907060號函廠商核定。109.07.24驗廠取樣。109.08.14 315W廠拌。109.08.28 80、245、280、350SCC廠拌)。 竑榮官田廠:109.08.14棪嘉南(A2)監字第10908022號函廠商核定。109.08.25驗廠取樣。109.10.06 80、175、245、280、315W廠拌。 竑榮安定廠:109.08.14棪嘉南(A2)監字第10908023號函廠商核定。109.08.31驗廠取樣。109.10.07 80、175、245、280廠拌。
B7: 結構用混凝土，80kgf/cm2 | F7: 109/07/13 | G7: 109/07/24
B8: 壹、一、1 結構工程 10 | C8: 955 | D8: M3 | E8: 是 | F8: 109/07/20 | G8: 是 | H8: P | J8: P
B9: 結構用混凝土，280kgf/cm2(墩柱補強) | F9: 109/07/13 | G9: 109/07/24
B10: 壹、一、1 結構工程 11 | C10: 4450 | D10: M3 | E10: 是 | F10: 109/07/20 | G10: 是 | H10: P | J10: P
B11: 結構用混凝土，280kgf/cm2(帽梁及其他補強) | F11: 109/07/13 | G11: 109/07/24
B12: 壹、一、1 結構工程 13、14 | C12: 38313 | D12: M3 | E12: 是 | F12: 109/07/20 | G12: 是 | H12: P | J12: P | M12: 核定
B13: 自充填混凝土，350kgf/cm2 | F13: 109/07/13 | G13: 109/07/24 | M13: 提送核定版
B14: 壹、一、3 排水復舊及臨時導排水工程 5 | C14: 116 | D14: M3 | E14: 是 | F14: 109/07/20 | G14: 是 | H14: P | J14: P | M14: 109.7.15
B15: 結構用混凝土，80kgf/cm2 | F15: 109/07/13 | G15: 109/07/24 | M15: 提送核定版
B16: 壹、一、3 排水復舊及臨時導排水工程 6 | C16: 1921 | D16: M3 | E16: 是 | F16: 109/07/20 | G16: 是 | H16: P | J16: P | M16: 109.7.15
B17: 結構用混凝土，245kgf/cm2 | F17: 109/07/13 | G17: 109/07/24 | M17: 提送核定版
A18: 2 | B18: 壹、一、2 大地擋土工程 28 | C18: 2066 | D18: M3 | E18: 是 | F18: 110/07/20 | G18: 是 | H18: P | J18: P | M18: 109/09/30(水泥) 109/10/20(砂石) 109/09/30(點焊鋼絲網) | N18: 晉瑜水泥:109.09.30棪嘉南(A2)監字第10909065號函廠商核定。(水泥) 永福鑫:109.10.20棪嘉南(A2)監字第10910044號函廠商核定。(砂石)109.12.30廠驗。 三發製網:109.09.30棪嘉南(A2)監字第10909068號函廠商核定。(點焊鋼絲網)109.10.26廠驗。
B19: 噴凝土(5cm厚，含點焊鋼絲網、錨筋及洩水孔)及拆除 | F19: 109/10/14(砂石) 109/09/28(水泥) 109/09/28(點焊鋼絲網) | G19: 109/12/30(砂石) 109/10/23(鋼絲網)
B20: 壹、一、3 排水復舊及臨時導排水工程 8 | C20: 5 | D20: M3 | E20: 是 | F20: 110/07/20 | G20: 是 | H20: P | J20: P | M20: 核定
B21: 噴凝土，抗壓強度175kgf/cm2 | F21: 109/10/14(砂石) 109/09/28(水泥) 109/09/28(點焊鋼絲網) | G21: 109/12/30(砂石) 109/10/23(鋼絲網)
A22: 3 | B22: 壹、一、1 結構工程 12 | C22: 15 | D22: M3 | E22: 是 | F22: 109/08/31 | G22: 否 | H22: P | J22: P | M22: 109/08/17 | N22: 交峯:10908.17棪嘉南(A2)監字第10908025號函廠商核定。
B23: 無收縮水泥砂漿，抗壓強度350 kgf/cm2 | F23: 109/08/10 | M23: 核定
A24: 4 | B24: 壹、一、1 結構工程 15 | C24: 3178 | D24: T | E24: 是 | F24: 109/07/30 | G24: 是 | H24: P | J24: P | M24: 109/07/20(志一) 109/09/30(海光、漢泰、協勝發) | N24: 志一:109.07.20棪嘉南(A2)監字第10907034號函廠商核定。109.08.05(驗廠) 漢泰:109.09.30棪嘉南(A2)監字第10909071號函廠商核定。 海光:109.09.30棪嘉南(A2)監字第10909072號函廠商核定。 協勝發:109.09.30棪嘉南(A2)監字第10909073號函廠商核定。 (海光、漢泰、協勝發109.10.05驗廠合格)
B25: 鋼筋，SD420W | F25: 109/07/13 | G25: 109/08/05
B26: 壹、一、3 排水復舊及臨時導排水工程 7 | C26: 79 | D26: T | E26: 是 | F26: 109/07/30 | G26: 是 | H26: P | J26: P | M26: 核定
B27: 鋼筋，SD420W | F27: 109/07/13 | G27: 109/08/05
A28: 5 | B28: 壹、一、1 結構工程 18 | C28: 70 | D28: T | E28: 是 | F28: 110/9/30 | G28: 否 | H28: P | J28: P | M28: 110/09/07 | N28: 達盈:110.09.07棪嘉南(A2)監字第1100657號函廠商核定
B29: 橋墩鋼板包覆，A36 | F29: 110/09/07 | M29: 核定
A30: 6 | B30: 壹、一、1 結構工程 19 | C30: 105 | D30: T | E30: 是 | F30: 111/02/20 | G30: 否 | H30: P | J30: P
B31: 鋼板止震裝置，A709/A572 GR.50
A32: 7 | B32: 壹、一、1 結構工程 20 | C32: 438 | D32: M2 | E32: 是 | F32: 110/10/30 | G32: 否 | H32: P | I32: P | J32: P | M32: 110/10/14 | N32: 諦佑:110.10.14棪嘉南(A2)監字第1100737號函廠商核定
B33: 鋼板外露表面油漆 | F33: 110/10/13 | M33: 核定
B34: 壹、一、1 結構工程 21 | C34: 437 | D34: M2 | E34: 是 | F34: 110/10/30 | G34: 否 | H34: P | I34: P | J34: P | M34: 110/10/14
B35: 鋼板內面防鏽油漆 | F35: 110/10/13 | M35: 核定
A36: 8 | B36: 壹、一、1 結構工程 22~24 | C36: 175438 | D36: 支 | E36: 是 | F36: 109/09/15 | G36: 否 | H36: P | I36: P | J36: P | M36: 109/08/26 | N36: 台灣飛魚:109.08.26棪嘉南(A2)監字第10908046號函廠商核定。109.09.03施工說明會。109.10.12施工前拉拔試驗(合格)。 喜利得:109.09.08棪嘉南(A2)監字第10909020號函廠商核定。109.09.07施工說明會。109.10.13施工前拉拔試驗(合格)。
B37: 化學黏著錨筋，16mm∮ | F37: 109/08/19
B38: 壹、一、1 結構工程 25 | C38: 52992 | D38: 支 | E38: 是 | F38: 109/09/15 | G38: 否 | H38: P | I38: P | J38: P
B39: 化學黏著錨筋，19mm∮ | F39: 109/08/19 | M39: 台灣飛魚藥劑核定
B40: 壹、一、1 結構工程 26~27 | C40: 30452 | D40: 支 | E40: 是 | F40: 109/09/15 | G40: 否 | H40: P | I40: P | J40: P
B41: 化學黏著錨筋，22mm∮ | F41: 109/08/19
...

Sheet 材料 設備檢(試)驗管制總表 202112
A1: 國道高速公路後續路段橋梁耐震補強工程(區段2-1)第M38A2標-烏山頭新化段 材料設備檢(試)驗管制總表
A2: 項次 | B2: 契約詳細表項次 | C2: 預定進場日期 | D2: 進場 數量 | F2: 抽樣日期 | J2: 規定抽(取)樣 頻率 | K2: 累積進場數量 | L2: 抽試驗 結果 | M2: 抽驗及會同 | N2: 備註
B3: 材料(設備)名稱 | C3: 實際進場日期 | F3: 抽樣數量 | K3: 累積抽樣數量 | M3: 人員 | N3: (歸檔編號)
A4: 1 | B4: 水泥預拌混凝土廠驗廠-配合設備 | C4: 109/07/24 | D4: 1 | E4: 式 | F4: 109/07/24(贊洲) 109/08/25(竑榮官田) 109/08/31(竑榮安定) | J4: 1式 | K4: 1式 | L4: 合格 | M4: 監造:李秉融 | N4: M38A2-J-a-C1-001(贊洲) M38A2-J-a-C1-004(竑榮官田) MA38A2-J-a-C1-007(竑榮安定)
B5: 拌和廠 | C5: 109/07/24(贊洲) 109/08/25(竑榮官田) 109/08/31(竑榮安定) | F5: 一式 | K5: 1式 | M5: 威勝:柯志龍
B6: 水泥預拌混凝土廠驗廠-配合設備 | C6: 109/07/24 | D6: 1 | E6: 式 | F6: 109/07/24(贊洲) 109/08/25(竑榮官田) 109/08/31(竑榮安定) | J6: 1式 | K6: 1式 | L6: 合格 | M6: 監造:李秉融 | N6: M38A2-J-a-C1-001(贊洲) M38A2-J-a-C1-004(竑榮官田) MA38A2-J-a-C1-007(竑榮安定)
B7: 粒料儲藏 | C7: 109/07/24(贊洲) 109/08/25(竑榮官田) 109/08/31(竑榮安定) | F7: 一式 | K7: 1式 | M7: 威勝:柯志龍
B8: 水泥預拌混凝土廠驗廠-配合設備 | C8: 109/07/24 | D8: 1 | E8: 式 | F8: 109/07/24(贊洲) 109/08/25(竑榮官田) 109/08/31(竑榮安定) | J8: 1式 | K8: 1式 | L8: 合格 | M8: 監造:李秉融 | N8: M38A2-J-a-C1-001(贊洲) M38A2-J-a-C1-004(竑榮官田) MA38A2-J-a-C1-007(竑榮安定)
B9: 配合設備 | C9: 109/07/24(贊洲) 109/08/25(竑榮官田) 109/08/31(竑榮安定) | F9: 一式 | K9: 1式 | M9: 威勝:柯志龍
B10: 水泥預拌混凝土廠驗廠-配合設備 | C10: 109/07/24 | D10: 1 | E10: 式 | F10: 109/07/24(贊洲) 109/08/25(竑榮官田) 109/08/31(竑榮安定) | J10: 1式 | K10: 1式 | L10: 合格 | M10: 監造:李秉融 | N10: M38A2-J-a-C1-001(贊洲) M38A2-J-a-C1-004(竑榮官田) MA38A2-J-a-C1-007(竑榮安定)
B11: 計量設備 | C11: 109/07/24(贊洲) 109/08/25(竑榮官田) 109/08/31(竑榮安定) | F11: 一式 | K11: 1式 | M11: 威勝:柯志龍
B12: 水泥預拌混凝土廠驗廠-配合設備 | C12: 109/07/24 | D12: 1 | E12: 式 | F12: 109/07/24(贊洲) 109/08/25(竑榮官田) 109/08/31(竑榮安定) | J12: 1式 | K12: 1式 | L12: 合格 | M12: 監造:李秉融 | N12: M38A2-J-a-C1-001(贊洲) M38A2-J-a-C1-004(竑榮官田) MA38A2-J-a-C1-007(竑榮安定)
B13: 運輸設備 | C13: 109/07/24(贊洲) 109/08/25(竑榮官田) 109/08/31(竑榮安定) | F13: 一式 | K13: 1式 | M13: 威勝:柯志龍
B14: 水泥預拌混凝土廠驗廠-配合設備 | C14: 109/07/22 | D14: 1 | E14: 式 | F14: 109/07/24(贊洲) 109/08/25(竑榮官田) | J14: 1式 | K14: 1式 | L14: 合格 | M14: 監造:李秉融 | N14: M38A2-J-a-C1-002(贊洲) M38A2-J-a-C1-005(竑榮官田)
B15: 水泥 | C15: 109/07/24(贊洲) 109/08/25(竑榮官田) | F15: 一式 | K15: 1式 | M15: 威勝:柯志龍
B16: 水泥預拌混凝土廠驗廠-配合設備 | C16: 109/07/22 | D16: 1 | E16: 式 | F16: 109/07/24(贊洲) 109/08/25(竑榮官田) | J16: 1式 | K16: 1式 | L16: 合格 | M16: 監造:李秉融 | N16: M38A2-J-a-C1-002(贊洲) M38A2-J-a-C1-005(竑榮官田)
B17: 細粒料 | C17: 109/07/24(贊洲) 109/08/25(竑榮官田) | F17: 一式 | K17: 1式 | M17: 威勝:柯志龍
B18: 水泥預拌混凝土廠驗廠-配合設備 | C18: 109/07/22 | D18: 1 | E18: 式 | F18: 109/07/24(贊洲) 109/08/25(竑榮官田) | J18: 1式 | K18: 1式 | L18: 合格 | M18: 監造:李秉融 | N18: M38A2-J-a-C1-002(贊洲) M38A2-J-a-C1-005(竑榮官田)
B19: 粗粒料 | C19: 109/07/24(贊洲) 109/08/25(竑榮官田) | F19: 一式 | K19: 1式 | M19: 威勝:柯志龍
B20: 水泥預拌混凝土廠驗廠-配合設備 | C20: 109/07/22 | D20: 1 | E20: 式 | F20: 109/07/24(贊洲) 109/08/25(竑榮官田) 109/08/31(竑榮安定) | J20: 1式 | K20: 1式 | L20: 合格 | M20: 監造:李秉融 | N20: M38A2-J-a-C1-002(贊洲) M38A2-J-a-C1-005(竑榮官田) MA38A2-J-a-C1-008(竑榮安定)
B21: 拌和水 | C21: 109/07/24(贊洲) 109/08/25(竑榮官田) 109/08/31(竑榮安定) | F21: 一式 | K21: 1式 | M21: 威勝:柯志龍
A22: 1 | B22: 水泥預拌混凝土廠驗廠-配合設備 | C22: 109/07/22 | D22: 1 | E22: 式 | F22: 109/07/24(贊洲) 109/08/25(竑榮官田) | J22: 1式 | K22: 1式 | L22: 合格 | M22: 監造:李秉融 | N22: M38A2-J-a-C1-002(贊洲) M38A2-J-a-C1-005(竑榮官田)
B23: 飛灰 | C23: 109/07/24(贊洲) 109/08/25(竑榮官田) | F23: 一式 | K23: 1式 | M23: 威勝:柯志龍
B24: 水泥預拌混凝土廠驗廠-配合設備 | C24: 109/07/22 | D24: 1 | E24: 式 | F24: 109/07/24(贊洲) 109/08/25(竑榮官田) | J24: 1式 | K24: 1式 | L24: 合格 | M24: 監造:李秉融 | N24: M38A2-J-a-C1-002(贊洲) M38A2-J-a-C1-005(竑榮官田)
B25: 高爐石粉 | C25: 109/07/24(贊洲) 109/08/25(竑榮官田) | F25: 一式 | K25: 1式 | M25: 威勝:柯志龍
B26: 水泥預拌混凝土廠驗廠-配合設備 | C26: 109/07/22 | D26: 1 | E26: 式 | F26: 109/07/24(贊洲) 109/08/25(竑榮官田) | J26: 1式 | K26: 1式 | L26: 合格 | M26: 監造:李秉融 | N26: M38A2-J-a-C1-002(贊洲) M38A2-J-a-C1-005(竑榮官田)
B27: 化學摻劑 | C27: 109/07/24(贊洲) 109/08/25(竑榮官田) | F27: 一式 | K27: 1式 | M27: 威勝:柯志龍
B28: 水泥預拌混凝土廠驗廠-配合設備 | C28: 109/07/22 | D28: 1 | E28: 式 | F28: 109/07/24(贊洲) 109/08/25(竑榮官田) | J28: 1式 | K28: 1式 | L28: 合格 | M28: 監造:李秉融 | N28: M38A2-J-a-C1-002(贊洲) M38A2-J-a-C1-005(竑榮官田)
B29: 配和設計 | C29: 109/07/24(贊洲) 109/08/25(竑榮官田) | F29: 一式 | K29: 1式 | M29: 威勝:柯志龍
B30: 水泥預拌混凝土廠驗廠-配合設備 | C30: 109/07/22 | D30: 1 | E30: 式 | F30: 109/08/26(贊洲) 109/10/06(竑榮官田) 109/10/07(竑榮安定) | J30: M3≦50 取2組，50≦M3<100 取樣3組，每加100M3加取一組。 | K30: 1式 | L30: 合格 | M30: 監造:李秉融 | N30: M38A2-J-a-C1-006(贊洲) M38A2-J-a-C1-009(竑榮官田) MA38A2-J-a-C1-010(竑榮安定)
B31: 80 kgf/cm2廠拌配合設計 | C31: 109/08/26(贊洲) 109/10/06(竑榮官田) 109/10/07(竑榮安定) | F31: 一式 | K31: 1式 | M31: 威勝:柯志龍
B32: 水泥預拌混凝土廠驗廠-配合設備 | C32: 109/07/22 | D32: 1 | E32: 式 | F32: 109/08/26(贊洲) 109/10/06(竑榮官田) 109/10/07(竑榮安定) | J32: M3≦50 取2組，50≦M3<100 取樣3組，每加100M3加取一組。 | K32: 1式 | L32: 合格 | M32: 監造:李秉融 | N32: M38A2-J-a-C1-006(贊洲) M38A2-J-a-C1-009(竑榮官田) MA38A2-J-a-C1-010(竑榮安定)
B33: 245 kgf/cm2廠拌配合設計 | C33: 109/08/26(贊洲) 109/10/06(竑榮官田) 109/10/07(竑榮安定) | F33: 一式 | K33: 1式 | M33: 威勝:柯志龍
B34: 水泥預拌混凝土廠驗廠-配合設備 | C34: 109/07/22 | D34: 1 | E34: 式 | F34: 109/08/26(贊洲) 109/10/06(竑榮官田) 109/10/07(竑榮安定) | J34: M3≦50 取2組，50≦M3<100 取樣3組，每加100M3加取一組。 | K34: 1式 | L34: 合格 | M34: 監造:李秉融 | N34: M38A2-J-a-C1-006(贊洲) M38A2-J-a-C1-009(竑榮官田) MA38A2-J-a-C1-010(竑榮安定)
B35: 280 kgf/cm2廠拌配合設計 | C35: 109/08/26(贊洲) 109/10/06(竑榮官田) 109/10/07(竑榮安定) | F35: 一式 | K35: 1式 | M35: 威勝:柯志龍
B36: 水泥預拌混凝土廠驗廠-配合設備 | C36: 109/07/22 | D36: 1 | E36: 式 | F36: 109/08/26(贊洲) 109/11/19(竑榮官田) 109/12/28(竑榮安定) | J36: M3≦50 取2組，50≦M3<100 取樣3組，每加100M3加取一組。 | K36: 1式 | L36: 合格 | M36: 監造:李秉融 | N36: M38A2-J-a-C1-006(贊洲) M38A2-J-a-C1-012(竑榮官田) MA38A2-J-a-C1-013(竑榮安定)
B37: 350SCC kgf/cm2廠拌配合設計 | C37: 109/08/26(贊洲) 109/11/19(竑榮官田) 109/12/28(竑榮安定) | F37: 一式 | K37: 1式 | M37: 威勝:柯志龍
B38: 水泥預拌混凝土廠驗廠-配合設備 | C38: 109/08/28 | D38: 1 | E38: 式 | F38: 109/08/14(贊洲) 109/10/06(竑榮官田) 109/11/13(竑榮安定) | J38: M3≦50 取2組，50≦M3<100 取樣3組，每加100M3加取一組。 | K38: 1式 | L38: 合格 | M38: 監造:李秉融 | N38: M38A2-J-a-C1-003(贊洲) M38A2-J-a-C1-009(竑榮官田) MA38A2-J-a-C1-011(竑榮安定)
B39: 315 kgf/cm2廠拌配合設計 | C39: 109/08/14(贊洲) 109/10/06(竑榮官田) 109/11/13(竑榮安定) | F39: 一式 | K39: 1式 | M39: 威勝:柯志龍
B40: 壹.一.1 .9 、壹.一.3.5 | C40: 109/07/22 | D40: 1528 | E40: M3 | F40: 110/11/17(贊洲) 110/12/17(竑榮官田) | J40: M3≦50 取2組，50≦M3<100 取樣3組，每加100M3加取一組。 | K40: =298+234 -> 532 | L40: 合格 | M40: 監造:吳英傑 | N40: M38A2-J-a-C4A-380(贊洲) M38A2-J-a-C4B-215(竑榮官田)
...

Sheet 材料與設備試驗管制總表
A1: 國道1號265k+286排水箱涵改建工程 材料設備檢(試)驗管制總表
A2: 項次 | B2: 契約詳細表項次 | C2: 預定進場日期 | D2: 進場 數量 | F2: 抽樣日期 | J2: 規定抽樣 頻率 | K2: 累積進場數量 | L2: 檢(試)驗 結果 | M2: 檢(試)及會同 | N2: 備註
B3: 材料(設備)名稱 | C3: 實際進場日期 | F3: 抽樣數量 | K3: 累積抽樣數量 | M3: 人員 | N3: (歸檔編號、報告編號)
B4: 水泥 | C4: 112/04/12 | D4: 廠驗 | F4: 112/04/12 | J4: 廠驗 | K4: 廠驗 | L4: 合格 | M4: 主辦：謝孟承 監造：邱俊榮 | N4: 265K-J-a-C1-002 SGS KB-23-03280-C-23-08984、 RKG23000490Y
C5: 112/04/12(廠驗) | F5: 廠驗 | K5: 廠驗 | M5: 威勝:杜文斌、黃淑惠
B6: 細粒料 | C6: 112/04/12 | D6: 廠驗 | F6: 112/04/12 | J6: 每半年 | K6: 廠驗 | L6: 合格 | M6: 主辦：謝孟承 監造：邱俊榮 | N6: 265K-J-a-C1-002 SGS KB-23-03283-C-23-08987
C7: 112/04/12(廠驗) | F7: 1 | K7: =F7 -> 1 | M7: 威勝:杜文斌、黃淑惠
B8: 細粒料 | C8: 112/10/11 | D8: 112年 第二季取樣 | F8: =C9 -> 112/10/04 | J8: 每半年 | K8: =D8 -> 112年 第二季取樣 | L8: 合格 | M8: 監造：顧永春 | N8: 265K-J-a-C1-007 KB-23-09301-C-23-23462
C9: 112/10/04 | F9: 1 | K9: =F9+K7 -> 2 | M9: 威勝：杜文斌
B10: 細粒料 | C10: 113/04/04 | D10: 113年 半年度第一次取樣 | F10: =C11 -> 113/03/28 | J10: 每半年 | K10: =D10 -> 113年 半年度第一次取樣 | L10: 合格 | M10: 監造：葉致廷 | N10: 265K-J-a-C1-010 SGS斗六實驗室 TB-24-02104、C-24-05292 KB-24-03977、C-24-09345
C11: 113/03/28 | F11: 1 | K11: =F11+K9 -> 3 | M11: 威勝：杜文斌
B12: 細粒料 | C12: 113/09/28 | D12: 113年 半年度第二次取樣 | F12: =C13 -> 113/09/26 | J12: 每半年 | K12: =D12 -> 113年 半年度第二次取樣 | L12: 合格 | M12: 監造：葉致廷 | N12: 265K-J-a-C1-014 SGS斗六實驗室 TB-24-07188、C-24-17240 KB-24-10352、C-24-27268
C13: 113/09/26 | F13: 1 | K13: =F13+K11 -> 4 | M13: 威勝：杜文斌
B14: 細粒料 | C14: 114/03/12 | D14: 114年 半年度第一次取樣 | F14: =C15 -> 114/03/12 | J14: 每半年 | K14: =D14 -> 114年 半年度第一次取樣 | L14: 合格 | M14: 監造：葉致廷 | N14: 265K-J-a-C1-015 SGS斗六實驗室 TB-25-01452、C-25-03731、KB-25-02260、C-25-07228
C15: 114/03/12 | F15: 1 | K15: =F15+K13 -> 5 | M15: 威勝：杜文斌
B16: 粗粒料 | C16: 112/04/12 | D16: 廠驗 | F16: 112/04/12 | J16: 每半年 | K16: 廠驗 | L16: 合格 | M16: 主辦：謝孟承 監造：邱俊榮 | N16: 265K-J-a-C1-002 SGS KB-23-03283-C-23-08987
C17: 112/04/12(廠驗) | F17: 1 | K17: =F17 -> 1 | M17: 威勝:杜文斌、黃淑惠
B18: 粗粒料 | C18: 112/10/11 | D18: 112年 第二季取樣 | F18: =C19 -> 112/10/04 | J18: 每半年 | K18: =D18 -> 112年 第二季取樣 | L18: 合格 | M18: 監造：顧永春 | N18: 265K-J-a-C1-007 KB-23-09301-C-23-23462
C19: 112/10/04 | F19: 1 | K19: =F19+K17 -> 2 | M19: 威勝：杜文斌
B20: 粗粒料 | C20: 113/04/04 | D20: 113年 半年度第一次取樣 | F20: =C21 -> 113/03/28 | J20: 每半年 | K20: =D20 -> 113年 半年度第一次取樣 | L20: 合格 | M20: 監造：葉致廷 | N20: 265K-J-a-C1-010 SGS斗六實驗室 TB-24-02104、C-24-05292 KB-24-03977、C-24-09345
C21: 113/03/28 | F21: 1 | K21: =F21+K19 -> 3 | M21: 威勝：杜文斌
B22: 粗粒料 | C22: 113/09/28 | D22: 113年 半年度第二次取樣 | F22: =C23 -> 113/09/26 | J22: 每半年 | K22: =D22 -> 113年 半年度第二次取樣 | L22: 合格 | M22: 監造：葉致廷 | N22: 265K-J-a-C1-014 SGS斗六實驗室 TB-24-07188、C-24-17240 KB-24-10352、C-24-27268
C23: 113/09/26 | F23: 1 | K23: =F23+K21 -> 4 | M23: 威勝：杜文斌
B24: 粗粒料 | C24: 114/03/12 | D24: 114年 半年度第一次取樣 | F24: =C25 -> 114/03/12 | J24: 每半年 | K24: =D24 -> 114年 半年度第一次取樣 | L24: 合格 | M24: 監造：葉致廷 | N24: 265K-J-a-C1-015 SGS斗六實驗室 TB-25-01452、C-25-03731、KB-25-02260、C-25-07228
C25: 114/03/12 | F25: 1 | K25: =F25+K23 -> 5 | M25: 威勝：杜文斌
B26: 拌和水 | C26: 112/04/12 | D26: 廠驗 | F26: 112/04/12 | J26: 每半年 | K26: 廠驗 | L26: 合格 | M26: 主辦：謝孟承 監造：邱俊榮 | N26: 265K-J-a-C1-002 SGS RKG23000492Y KB-23-03279-C-23-08983
C27: 112/04/12(廠驗) | F27: 1 | K27: =F27 -> 1 | M27: 威勝:杜文斌、黃淑惠
B28: 拌和水 | C28: 112/10/11 | D28: 112年 第二季取樣 | F28: =C29 -> 112/10/04 | J28: 每半年 | K28: =D28 -> 112年 第二季取樣 | L28: 合格 | M28: 監造：顧永春 | N28: 265K-J-a-C1-007 SGS-23-09300-C-23-23461
C29: 112/10/04 | F29: 1 | K29: =F29+K27 -> 2 | M29: 威勝：杜文斌
B30: 拌和水 | C30: 113/04/04 | D30: 113年 半年度第一次取樣 | F30: =C31 -> 113/03/28 | J30: 每半年 | K30: =D30 -> 113年 半年度第一次取樣 | L30: 合格 | M30: 監造：葉致廷 | N30: 265K-J-a-C1-010 SGS斗六實驗室 KB-24-03978、C-24-09346 RKG24000647
C31: 113/03/28 | F31: 1 | K31: =F31+K29 -> 3 | M31: 威勝：杜文斌
B32: 拌和水 | C32: 113/09/28 | D32: 113年 半年度第二次取樣 | F32: =C33 -> 113/09/26 | J32: 每半年 | K32: =D32 -> 113年 半年度第二次取樣 | L32: 合格 | M32: 監造：葉致廷 | N32: 265K-J-a-C1-014 SGS斗六實驗室 RKG24001654、KB-24-10353 C-24-27269
C33: 113/09/26 | F33: 1 | K33: =F33+K31 -> 4 | M33: 威勝：杜文斌
B34: 拌和水 | C34: 114/03/12 | D34: 114年 半年度第一次取樣 | F34: =C35 -> 114/03/12 | J34: 每半年 | K34: =D34 -> 114年 半年度第一次取樣 | L34: 合格 | M34: 監造：葉致廷 | N34: 265K-J-a-C1-015 SGS斗六實驗室 RKG25000382、KB-25-02259 C-25-07227
C35: 114/03/12 | F35: 1 | K35: =F35+K33 -> 5 | M35: 威勝：杜文斌
B36: 飛灰 | C36: 112/04/12 | D36: 廠驗 | F36: 112/04/12 | J36: 廠驗 | K36: 廠驗 | L36: 合格 | M36: 主辦：謝孟承 監造：邱俊榮 | N36: 265K-J-a-C1-002 SGS RKG23000493Y KB-23-03282-C-23-08986
C37: 112/04/12(廠驗) | F37: 廠驗 | K37: 廠驗 | M37: 威勝:杜文斌、黃淑惠
B38: 高爐石粉 | C38: 112/04/12 | D38: 廠驗 | F38: 112/04/12 | J38: 廠驗 | K38: 廠驗 | L38: 合格 | M38: 主辦：謝孟承 監造：邱俊榮 | N38: 265K-J-a-C1-002 SGS- KB-23-03281-C-23-08985、 RKG23000491Y
C39: 112/04/12(廠驗) | F39: 廠驗 | K39: 廠驗 | M39: 威勝:杜文斌、黃淑惠
B40: 化學摻劑 | C40: 112/04/12 | D40: 廠驗 | F40: 112/04/12 | J40: 每半年 | K40: 廠驗 | L40: 合格 | M40: 主辦：謝孟承 監造：邱俊榮 | N40: 265K-J-a-C1-002 SGS-佑聲SP-150 KB-23-03403-1-C-23-09305 HB-23-02627-C-23-11032 SGS-明氏MC-2188 KB-23-03402-1-C-23-09304 HB-23-02629-C-23-11034
...

Sheet 材料設備送審及進場時程管制總表
A1: 國道1號265k+286排水箱涵改建工程 材料設備送審管制總表
A2: 項次 | B2: 契約詳細表項次 | C2: 契約數量 | E2: 是否 取樣試驗 | F2: 預訂送審日期 | G2: 是否驗廠 | H2: 送審資料(P) | M2: 審查日期 | N2: 備註 (歸檔編號) (報告編號)
H3: 協力廠商資料 | I3: 型錄 | J3: 相關試驗報告 | K3: 樣品 | L3: 其他
B4: 材料(設備)名稱 | F4: 實際送審日期 | G4: 驗廠日期 | M4: 審查結果
A6: 1 | B6: 壹.甲.(B.5、B.12、D.1、E.1、H.1) | C6: 2702 | D6: M3 | E6: 是 | F6: 112/03/20 | G6: 是 | H6: P | J6: P | L6: 配比 資料 | M6: 112/03/30 | N6: 265K-U-a-材料/設備 112年3月24日聯嘉字第1120324003號函廠商核定 112年3月30日南新字第1120010760號函廠商核定 112.04.12驗廠取樣。 112.04.18試拌(175、245、280、280早強、315W、420) 112.04.21廠拌(175、245、280、280早強、315W、420) 112.05.18試拌(420) 112.08.11廠拌(420) 112年12月6日聯嘉字第1121206006號函廠商核定 112年12月21日南新字第1125162149號函廠商核定 113.01.03試拌(新配比420) 113.01.19廠拌(新配比420) 113年6月3日聯嘉字第1130603001號函廠商核定(420無收縮混凝土) 1136月11日南新字第1135160955號函廠商核定(420無收縮混凝土)
B7: 280kgf/cm2混凝土 | F7: 112/03/20 | G7: 112/04/12
B8: 壹.甲.(A.13、A.14、B.6、E.1) | C8: 179 | D8: M3 | E8: 否 | F8: 112/03/20 | G8: 是 | H8: P | J8: P
B9: 80kgf/cm2混凝土 | F9: 112/03/20 | G9: 112/04/12
B10: 壹.甲.(A.10、A.13、A14、D.2、F.2、F.6、K.5) | C10: 1325 | D10: M3 | E10: 是 | F10: 112/03/20 | G10: 是 | H10: P | J10: P
B11: 245kgf/cm2混凝土 | F11: 112/03/20 | G11: 112/04/12
B12: 壹.甲.(C.1、C.2) | C12: 1404 | D12: M3 | E12: 是 | F12: 112/03/20 | G12: 是 | H12: P | J12: P
B13: 結構用混凝土，(機拌，水中)，315kgf/cm2 | F13: 112/03/20 | G13: 112/04/12
B14: 壹.甲.B.1 | C14: 1064 | D14: M3 | E14: 是 | F14: 112/03/20 | G14: 是 | H14: P | J14: P | M14: 同意核定
B15: 場鑄預力混凝土，420 kgf/cm2 | F15: 112/03/20 | G15: 112/04/12
B16: 壹.甲.(B.2、B.4) | C16: 52 | D16: M3 | E16: 是 | F16: 113/05/31 | G16: 否 | H16: P | J16: P
B17: 場鑄早強無收縮混凝土，420 kgf/cm2 | F17: 113/05/30 | G17: 否
B18: 壹.甲.B.3 | C18: 12 | D18: M3 | E18: 是 | F18: 112/03/20 | G18: 是 | H18: P | J18: P
B19: 早強混凝土280kgf/cm2 | F19: 112/03/20 | G19: 112/04/12
B20: 壹.甲.(G.2、G.3) | C20: 261 | D20: M3 | E20: 是 | F20: 112/03/20 | G20: 是 | H20: P | J20: P
B21: 175kgf/cm2混凝土 | F21: 112/03/20 | G21: 112/04/12
A22: 2 | B22: 壹.甲.(A.13、B.7、B12、B13、C.1、C.2、D.9、D10、E.1、H.1) | C22: 681 | D22: T | E22: 否 | F22: 112/03/25 | G22: 是 | H22: P | I22: P | J22: P | M22: 112/04/12 | N22: 265K-U-a-材料/設備 112年3月28日聯嘉字第1120328001號函廠商核定(志一) 112年4月12日南新字第1125160558號函廠商核定(志一) 112.04.14驗廠(志一) 112年12月27日聯嘉字第1121227001號函廠商核定(易利隆) 113年1月3日南新字第1135160001號函廠商核定(易利隆) 113年1月4日聯嘉字第1130104005號函廠商核定(東和) 113年2月16日南新字第1135160252號函廠商核定(東和) 113年1月4日聯嘉字第1130104005號函廠商核定(海光) 113年2月16日南新字第1135160252號函廠商核定(海光) 113年1月4日聯嘉字第1130104005號函廠商核定(漢泰) 113年2月16日南新字第1135160252號函廠商核定(漢泰)
B23: 鋼筋，SD420W | F23: 112/03/25 | G23: 112/04/14
A24: 2 | B24: 壹.甲.(A14、F6、G.2、G.3) | C24: 91 | D24: T | E24: 否 | F24: 112/03/25 | G24: 是 | H24: P | I24: P | J24: P | M24: 同意核定
B25: 鋼筋，SD280 | F25: 112/03/25 | G25: 112/04/14
A26: 2 | B26: 壹.甲.B.16 | C26: 80 | D26: 個 | E26: 是 | F26: 112/11/10 | G26: 否 | H26: P | I26: P | J26: P | M26: 112/11/23 | N26: 265K-U-a-材料/設備 112年11月7日聯嘉字第1121107001號函廠商核定 112年11月23日南新字第1125161934號函廠商核定
B27: 鋼筋，鋼筋續接器，D25 | F27: 112/11/01 | G27: 113/1/23
B28: 壹.甲.B.17 | C28: 92 | D28: 個 | E28: 是 | F28: 112/11/10 | G28: 否 | H28: P | I28: P | J28: P
B29: 鋼筋，鋼筋續接器，D22 | F29: 112/11/01 | G29: 113/1/23
B30: 壹.甲.B.18 | C30: 132 | D30: 個 | E30: 是 | F30: 112/11/10 | G30: 否 | H30: P | I30: P | J30: P
B31: 鋼筋，鋼筋續接器，D19 | F31: 112/11/01 | G31: 113/1/23 | M31: 同意核定
B32: 壹.甲.B.19 | C32: 48 | D32: 個 | E32: 是 | F32: 112/11/10 | G32: 否 | H32: P | I32: P | J32: P
B33: 鋼筋，鋼筋續接器，D16m | F33: 112/11/01 | G33: 113/1/23
B34: 壹.甲.B.20 | C34: 1009 | D34: 個 | E34: 是 | F34: 112/11/10 | G34: 否 | H34: P | I34: P | J34: P
B35: 鋼筋，鋼筋續接器，D13m | F35: 112/11/01 | G35: 113/1/23
A36: 3 | B36: 壹.甲.A.6 | C36: 1602 | D36: T | E36: 是 | F36: 112/03/20 | G36: 是 | H36: P | I36: P | J36: P | L36: 配比 資料 | M36: 112/04/20 | N36: 265K-U-a-材料/設備 112年3月22日聯嘉字第1120322002號函廠商核定 112年3月25日南新字第1120010714號函廠商審核後再提送 112年3月28日聯嘉字第1120322002號函廠商核定 112年4月17日聯嘉字第1120417002號函廠商核定 112年4月20日南新字第1120016157號函廠商核定 112.04.24驗廠 112.05.08瀝青混凝土配合比試拌(含油量及篩分析) 開放級配(改質IV-F型)、開放級配(AC-20)、密級配(改質IV-F型)、粗級配(AC-20) 112.06.12瀝青混凝土材料取樣
B37: 開放級配瀝青混凝土(改質Ⅳ-F型) | F37: 112/03/16 | G37: 112/04/24
B38: 壹.甲.A.7 | C38: 639 | D38: T | E38: 是 | F38: 112/03/20 | G38: 是 | H38: P | I38: P | J38: P
B39: 密級配瀝青混凝土(改質Ⅳ-F型) | F39: 112/03/16 | G39: 112/04/24
B40: 壹.甲.A.8 | C40: 899 | D40: T | E40: 是 | F40: 112/03/20 | G40: 是 | H40: P | I40: P | J40: P
B41: 瀝青處理底層 | F41: 112/03/16 | G41: 112/04/24 | M41: 同意核定
...

Sheet 三個月材料檢試驗管控表20240801~0831
A1: 國道1號265k+286排水箱涵改建工程
A2: 三個月材料檢試驗管控表
A4: 項次 | B4: 契約項次 | C4: 材料(設備)名稱 | D4: 契約數量 | E4: 預定 進場數量 | F4: 預定 取樣日期 | G4: 實際 取樣日期 | H4: 備註 | J4: 備註(2)
B5: 壹、甲、B 橋梁暨結構工程 B1~B3、B5~B6 | C5: 結構用混凝土 | D5: 1式 | E5: 1式 | F5: 112/03/27 | G5: 112/04/21 | H5: 112年 第一季取樣 | J5: 已完成(報告以歸檔)
B6: 壹、甲、B 橋梁暨結構工程 B1~B3、B5~B6 | C6: 結構用混凝土 | D6: 1式 | E6: 1式 | F6: 112/10/02 | G6: 112/10/04 | H6: 112年 第二季取樣 | J6: 已完成(報告以歸檔)
A7: 1 | B7: 壹、甲、B 橋梁暨結構工程 B1~B3、B5~B6 | C7: 結構用混凝土 | D7: 1式 | E7: 1式 | F7: 113/03/28 | G7: 113/03/28 | H7: 113年 半年度第一次取樣--SGS(試驗中)
A8: 2 | B8: 壹、甲、A 路工工程 A.10 | C8: 245kgf/cm2混凝土 | D8: 64 M3 | E8: 42 M3 | F8: 113/04/30 | G8: 113/04/30 | H8: 三個月合計方數:42m3 三個月合計: 2組試體 | J8: 1.1120505-工程告示牌基礎18.5立方 2.1120513~1120701-預鑄單面RC護欄總方數707立方 3.1120706-北上側施工便道56立方 4.1120928-北上側洗車台基礎及牆身19.5立方 5.1121115-南下側洗車台基礎及牆身18.5立方 6.1121123-北上側施工便道32立方 7.1121125-北上側及南下側施工便道32立方 8.1130430-路工工程A10，契約數量64立方(長度57公尺)，變更設計後的護欄長度為95公尺，變更後的數量須從新計算
A9: 3 | B9: 壹、甲、B 橋梁暨結構工程 B.5 | C9: 280kgf/cm2混凝土 | D9: 820 M3 | E9: 146.5 M3 | F9: 113/02/20 113/04/10 | G9: 113/04/10 | H9: 三個月合計方數:146.5m3 三個月合計: 9組試體 | J9: 累計日期:112/09/26~113/04/10 總累計方數:607m3 總累計試體組數:25組
A10: 4 | B10: 壹、甲、B 橋梁暨結構工程 B.1 | C10: 420kgf/cm2混凝土 | D10: 1064 M3 | E10: 342 M3 | F10: 113/04/18 | G10: 113/04/18 | H10: 試體製作累積組數:7組
B11: 壹.甲.A.路工工程 壹.甲.A.6 壹.甲.A.7 | C11: 瀝青混凝土 | D11: 1式 | E11: 1式 | F11: 112/06/12 | G11: 112/06/12 | H11: 試驗已完成(歸檔)
B12: 壹.甲.C.大地工程 壹.甲.C.1 橋下限高h≦10m | C12: 鋼筋，SD420W | D12: 170.62 T | E12: 88.53 T | F12: 112/11/20 112/12/29 | G12: 112/11/20 112/12/29 | H12: 試驗已完成(歸檔) | J12: 全套管鑽掘樁
B13: 壹.甲.C.大地工程 壹.甲.C.2 | C13: 鋼筋，SD420W | D13: 66.64 T | E13: 23.57 T | F13: 112/11/20 112/12/29 | G13: 112/11/20 112/12/29 | H13: 試驗已完成(歸檔) | J13: 全套管鑽掘樁
A14: 5 | B14: 壹、甲、B 橋梁暨結構工程 B.7 | C14: 鋼筋，SD420W | D14: 213 T | E14: 28.17 | F14: 113/03/15 | G14: 113/03/15 | H14: 累計: 104.87 T | J14: 113/01/10-A1與A2橋台(35.38T)，113/02/16-橋面板(41.32T)，113/03/15-中空梁版(28.17T)；合計104.87T
B15: 壹、甲、D 排水工程 D.4 | C15: 鋼筋，SD420W | D15: 156 T | E15: 28.17 | F15: - | G15: - | H15: 尚未使用
A16: 6 | B16: 壹、甲、A 路工工程 A.13 A.14 | C16: 鋼筋，SD420W | D16: - | E16: 33.01 T | F16: 113/04/17 | G16: 113/04/17 | H16: 擋土牆拓寬段變更設計中 竣葦實驗室 (試驗中) | J16: 加深型混凝土護欄(95m)、擋土牆拓寬段(50m)、擋土牆懸伸段(51m)，目前擋土牆拓寬段尚在變更當中無法計算出該段的鋼筋用量
B17: 壹.甲.C.大地工程 壹.甲.C.1、 壹.甲.C.2 | C17: 結構用混凝土，(機拌，水中)，315kgf/cm2， | D17: 1404 M3 | E17: 540 M3 | F17: 112/12/01 | G17: 112/12/09~113/1/12 | H17: 合計:603m3 共計:40組試體 試驗已完成 (歸檔)
B18: 壹.甲.C.大地工程 壹.甲.C.1 | C18: 鋼筋鋼套環 | D18: - | E18: 200顆 | F18: 112/08/31 | G18: 112/08/25 | H18: 試驗已完成(歸檔)
B19: 壹.甲.C.大地工程 壹.甲.C.8 | C19: 預力鋼腱地錨 | D19: 1056m | E19: 1056m | F19: 112/09/30 | G19: 112/09/21 112/09/25 | H19: 試驗已完成(歸檔)
B20: 壹.甲.E.交通工程 壹.甲.E.8 | C20: 防眩板 | D20: 710座 | E20: 840座 | F20: 112/09/15 | G20: 112/09/15 | H20: 試驗已完成(歸檔)
B21: 壹、甲、C 大地工程C.1(全套管鑽掘樁-限高) | C21: 鋼筋，SD420W | D21: 170.62 T | E21: 88.53 T | F21: 112/11/20 | G21: 112/11/20 | H21: 限高1支基樁鋼筋用量4.49T | J21: 目前已進貨20支限高基樁鋼筋用量，合約總數量:38支
B22: 壹、甲、C 大地工程 C.2 | C22: 鋼筋，SD420W | D22: 66.64 T | E22: 23.57 T | F22: 112/12/29 | G22: 112/12/29 | H22: 非限高1支基樁鋼筋用量4.76T | J22: 目前已進貨6支限高基樁鋼筋用量，合約總數量:14支
B23: 壹、甲、B 橋梁暨結構工程 B.20 | C23: 鋼筋，續接器(D13) | D23: 1009個 | E23: 80個 | F23: 113/01/15 | G23: 113/01/23 | H23: 華光(台南) 試驗合格 報告已歸檔 | J23: <1>D13鋼筋續接器-契約數量1009個，實際進貨數量1500個。 <2>D16鋼筋續接器-契約數量48個，實際進貨數量476個。 <3>D19鋼筋續接器-契約數量132個，實際進貨數量132個。 <4>D22鋼筋續接器-契約數量92個，實際進貨數量92個。 <5>D25鋼筋續接器-契約數量80個，實際進貨數量96個。 ★因D13與D16及D25鋼筋續接器，施工圖設計單位計算錯誤(中空梁版)，故辦理數量變更追加。
B24: 壹、甲、B 橋梁暨結構工程 B.18 | C24: 鋼筋，續接器(D19) | D24: 132個 | E24: 132個 | F24: 113/01/15 | G24: 113/01/23 | H24: 華光(台南) 試驗合格 報告已歸檔
B25: 壹、甲、B 橋梁暨結構工程 B.17 | C25: 鋼筋，續接器(D22) | D25: 92個 | E25: 92個 | F25: 113/01/15 | G25: 113/01/23 | H25: 華光(台南) 試驗合格 報告已歸檔
A26: 7 | B26: 壹、甲、B 橋梁暨結構工程 B.20 | C26: 鋼筋，續接器(D13) | D26: 1009個 | E26: 1420個 | F26: 113/03/26 | G26: 113/03/26 | H26: 華光(台南) 試驗合格
A27: 8 | B27: 壹、甲、B 橋梁暨結構工程 B.18 | C27: 鋼筋，續接器(D16) | D27: 48個 | E27: 476個 | F27: 113/03/26 | G27: 113/03/26 | H27: 華光(台南) 試驗合格
A28: 9 | B28: 壹、甲、B 橋梁暨結構工程 B.17 | C28: 鋼筋，續接器(D25) | D28: 80個 | E28: 96個 | F28: 113/03/26 | G28: 113/03/26 | H28: 華光(台南) 試驗合格
B29: 壹、甲、B 橋梁暨結構工程 B.1 | C29: 合成橡膠防震墊，60*30*5.7cm | D29: 66塊 | E29: 66塊 | F29: 113/01/15 | G29: 113/01/15 | H29: 合格 | J29: 製程檢驗:產製期間取樣辦理一次，施工技術規範05823規定
B30: 壹、甲、B 橋梁暨結構工程 B.5 | C30: 合成橡膠支承墊，15*15*3.0cm | D30: 98塊 | E30: 98塊 | F30: 113/01/15 | G30: 113/01/15 | H30: 合格 | J30: 製程檢驗:產製期間取樣辦理一次，施工技術規範05823規定
A31: 10 | B31: 壹、甲、B 橋梁暨結構工程 B.14 | C31: 橋面排水，橋面伸縮縫，C型 | D31: 74.94M | E31: 23.44M | F31: 113/03/15 | G31: 113/03/14 | H31: 明研 母材取樣 試驗合格
A32: 11 | B32: 壹、甲、B 橋梁暨結構工程 B.14 | C32: 橋面排水，橋面伸縮縫，C型-A1橋台 | D32: 74.94M | E32: 11.72M | F32: 113/04/30 | G32: 113/04/25 | H32: 統証 磁力檢測(MT)
A33: 12 | B33: 壹、甲、B 橋梁暨結構工程 B.5 | C33: 進橋板用，D=22mm2鍍鋅鋼棒 | D33: 98組 | E33: 98組 | F33: 113/03/18 | G33: 113/03/18 | H33: SGS 合格
B34: 壹.甲.A.7 | C34: 密級配瀝青混凝土 (改質IV-F型) | D34: 639T | E34: 740T | F34: 112/10/31 112/11/01 | G34: 112/10/31 112/11/01 | H34: 試驗已完成 (歸檔)
B35: 壹.甲.J.33 | C35: 開放級配瀝青混凝土 | D35: 3786T | E35: 170T | F35: 112/10/31 112/11/02 | G35: 112/10/31 112/11/02 | H35: 試驗已完成 (歸檔)
B36: 壹.甲.C.大地工程 壹.甲.C.1、 壹.甲.C.2 | C36: 焊材 | D36: 1式 | E36: 1式 | F36: 112/12/12 | G36: 112/12/07 | H36: 試驗已完成 (歸檔)
B37: 壹.甲.C.1、C2 | C37: 基樁-PVC塑膠硬質管 | D37: 7176 | E37: 1000 | F37: 112/12/08 | G37: 112/12/08 | H37: 試驗已完成 (歸檔)
A38: 13 | B38: 壹、甲、A 路工工程 A.10 | C38: 聚氯乙烯，A型， 150x9mm | D38: 23 M | E38: 40 M | F38: 113/02/06 | G38: 113/02/16 | H38: SGS 合格
A39: 14 | B39: 壹、甲、B 橋梁暨結構工程 B.5 | C39: 聚氯乙烯，B型，230x7.5mm | D39: 79 M | E39: 80 M | F39: 113/02/06 | G39: 113/02/16 | H39: SGS 合格
A40: 15 | B40: 壹、甲、A 路工工程 A.10、A.13、A.14 壹、甲、B 橋梁暨結構工程 B.1、B.5、B.15 | C40: 填縫板(1cm、2cm、3cm) | D40: 1式 | E40: 1式 | F40: 113/02/06 | G40: 113/02/16 | H40: SGS 合格 | J40: 契約數量1cm:30.73m2，進貨數量:10m2 契約數量2cm:197.503m2，進貨數量:25m2 契約數量3cm:29.7m2，進貨數量:10m2
A41: 16 | B41: 壹、甲、A 路工工程 A.10、A.13、A.14 壹、甲、B 橋梁暨結構工程 B.1、B.5、B.15 | C41: 填縫劑 | D41: 152.55 L | E41: 1式 | F41: 113/02/06 | G41: 113/02/16 | H41: SGS 合格 | J41: A劑進貨10桶(每桶6kg) B劑進貨10桶(每桶12kg)
...

Sheet 1140117(材料送審核定情形一覽表)
A1: 國道1號265k+286排水箱涵改建工程 材料設備送審管制總表
A2: 審查項次 | C2: 預計提送 | E2: 已提送 | G2: 已核定
A3: 材料送審資料 | C3: 34 | E3: 34 | G3: 31
A4: 備註 (交通部高速公路局南區養護分局尚未核定) | C4: 34 | E4: 34 | G4: 壹.甲.I.2：小葉榕 H*W≧150*80(cm) 壹.甲.B.21：維修道欄杆(橋台) 壹.甲.B.5：不銹鋼踏步，D=19mm ★上述三項材料送審資料為主辦機關尚未核定，監造單位已核定

Sheet 混凝土 80KGF CM3 贊洲
A1: 國道高速公路後續路段橋梁耐震補強工程(區段2-1)第M38A2標-烏山頭新化段 材料設備檢(試)驗管制總表 製表資料日期:110/02/18止
A2: 項次 | B2: 契約詳細表項次 | C2: 契約數量 | E2: 預定進場日期 | F2: 進場數量 | H2: 抽樣日期 | I2: 規定抽(取)樣頻率 | J2: 累積進場數量 | L2: 抽試驗結果 | M2: 抽驗及會同人員 | N2: 備註
B3: 材料(設備)名稱 | E3: 實際進場日期 | H3: 抽樣數量 | J3: 累積抽樣數量 | N3: (歸檔編號)
A4: 1 | B4: 壹、一、1 結構工程 9、3 排水復舊及臨時導排水工程 9 | C4: =1412+116 -> 1528 | D4: M3 | E4: 109/08/28 | F4: 一式 | H4: 109/08/28 | I4: V=每批數量(M3) V≦50 取樣2(組) 50≦V<100 取樣3組 100≦V<200 取樣4(組) V>200 INT(V/100)+取樣3(組)。 | J4: 一式 | L4: 合格 | M4: 監造單位:李秉融 | N4: 贊洲:109.07.28棪嘉南(A2)監字第10907060號函廠商核定。 109.07.24 驗廠取樣。 109.08.14 315W廠拌。 109.08.28 80、245、280、350SCC廠拌)。 M38A2-J-a-C1-006。 | O4: 1100224
B5: 結構用混凝土，80kgf/cm2 | E5: 109/08/28 | H5: 一式 | J5: 一式 | M5: 施工廠商:柯志龍
A6: 1-1 | B6: 壹、一、1 結構工程 9、3 排水復舊及臨時導排水工程 9 | C6: =1412+116 -> 1528 | D6: M3 | E6: 110/03/31 | F6: 24 | G6: M3 | H6: 110/01/09 | I6: V=每批數量(M3) V≦50 取樣2(組) 50≦V<100 取樣3組 100≦V<200 取樣4(組) V>200 INT(V/100)+取樣3(組)。 | J6: 24 | K6: M3 | L6: 合格 | M6: 監造單位:李之杰 | N6: M38A2-J-a-C4A-107 渡子頭二號橋P2L及P3L基礎PC
B7: 結構用混凝土，80kgf/cm2 | E7: 110/01/09 | H7: 2組 | J7: 2 | K7: 組 | M7: 施工廠商:林士興
A8: 1-2 | B8: 壹、一、1 結構工程 9、3 排水復舊及臨時導排水工程 9 | C8: =1412+116 -> 1528 | D8: M3 | E8: 110/01/15 | F8: 22 | G8: M3 | H8: 110/01/15 | I8: V=每批數量(M3) V≦50 取樣2(組) 50≦V<100 取樣3組 100≦V<200 取樣4(組) V>200 INT(V/100)+取樣3(組)。 | J8: 46 | K8: M3 | L8: 合格 | M8: 監造單位:吳英傑 | N8: M38A2-J-a-C4A-110 渡子頭二號橋P1L及P2R基礎PC
B9: 結構用混凝土，80kgf/cm2 | E9: 110/01/15 | H9: 2組 | J9: 4 | K9: 組 | M9: 施工廠商:石錦茹
A10: 1-3 | B10: 壹、一、1 結構工程 9、3 排水復舊及臨時導排水工程 9 | C10: =1412+116 -> 1528 | D10: M3 | E10: 110/03/02 | F10: 10 | G10: M3 | H10: 110/03/02 | I10: V=每批數量(M3) V≦50 取樣2(組) 50≦V<100 取樣3組 100≦V<200 取樣4(組) V>200 INT(V/100)+取樣3(組)。 | J10: 56 | K10: M3 | L10: 合格 | M10: 監造單位:李秉融 | N10: M38A2-J-a-C4A-166 渡子頭二號橋P3、P4R側基礎PC
B11: 結構用混凝土，80kgf/cm2 | E11: 110/03/02 | J11: 4 | K11: 組 | M11: 施工廠商:劉琮誠
A12: 1-4 | B12: 壹、一、1 結構工程 9、3 排水復舊及臨時導排水工程 9 | C12: =1412+116 -> 1528 | D12: M3 | E12: 110/03/09 | F12: 18.5 | G12: M3 | H12: 110/03/09 | I12: V=每批數量(M3) V≦50 取樣2(組) 50≦V<100 取樣3組 100≦V<200 取樣4(組) V>200 INT(V/100)+取樣3(組)。 | J12: 74.5 | K12: M3 | M12: 監造單位:李秉融 | N12: M38A2-J-a-C4A-175 渡子頭二號橋P1R、P4R側基礎PC
B13: 結構用混凝土，80kgf/cm2 | E13: 110/03/09 | J13: 4 | K13: 組 | M13: 施工廠商:林士興
A14: 1-5 | B14: 壹、一、1 結構工程 9、3 排水復舊及臨時導排水工程 9 | C14: =1412+116 -> 1528 | D14: M3 | E14: 110/03/18 | F14: 39 | G14: M3 | H14: 110/03/18 | I14: V=每批數量(M3) V≦50 取樣2(組) 50≦V<100 取樣3組 100≦V<200 取樣4(組) V>200 INT(V/100)+取樣3(組)。 | J14: 113.5 | K14: M3 | M14: 監造單位:吳英傑 | N14: M38A2-J-a-C4A-192 官田溪河川橋P9L側PC基礎
B15: 結構用混凝土，80kgf/cm2 | E15: 110/03/18 | H15: 2 | J15: 6 | K15: 組 | M15: 施工廠商:林士興
A16: 1-6 | B16: 壹、一、1 結構工程 9、3 排水復舊及臨時導排水工程 9 | C16: =1412+116 -> 1528 | D16: M3 | E16: 110/04/02 | F16: 10 | G16: M3 | H16: 110/04/02 | I16: V=每批數量(M3) V≦50 取樣2(組) 50≦V<100 取樣3組 100≦V<200 取樣4(組) V>200 INT(V/100)+取樣3(組)。 | J16: 123.5 | K16: M3 | M16: 監造單位:馮榮泉 | N16: M38A2-J-a-C4A-205 渡子頭一號橋P2L基礎PC
B17: 結構用混凝土，80kgf/cm2 | E17: 110/04/02 | J17: 6 | K17: 組 | M17: 施工廠商:石錦茹
A18: 1-7 | B18: 壹、一、1 結構工程 9、3 排水復舊及臨時導排水工程 9 | C18: =1412+116 -> 1528 | D18: M3 | E18: 110/05/04 | F18: 21 | G18: M3 | H18: 110/05/04 | I18: V=每批數量(M3) V≦50 取樣2(組) 50≦V<100 取樣3組 100≦V<200 取樣4(組) V>200 INT(V/100)+取樣3(組)。 | J18: =J16+F18 -> 144.5 | K18: M3 | M18: 監造單位:林東新 | N18: M38A2-J-a-C4A-235 官田溪河川橋P12L側基礎PC
B19: 結構用混凝土，80kgf/cm2 | E19: 110/05/04 | H19: 2 | J19: =J17+H19 -> 8 | K19: 組 | M19: 施工廠商:劉琮誠
A20: 1-8 | B20: 壹、一、1 結構工程 9、3 排水復舊及臨時導排水工程 9 | C20: =1412+116 -> 1528 | D20: M3 | E20: 110/05/17 | F20: 4.5 | G20: M3 | H20: 110/05/17 | I20: V=每批數量(M3) V≦50 取樣2(組) 50≦V<100 取樣3組 100≦V<200 取樣4(組) V>200 INT(V/100)+取樣3(組)。 | J20: =J18+F20 -> 149 | K20: M3 | M20: 監造單位:吳英傑 | N20: M38A2-J-a-C4A-251 官田溪河川P14R基礎PC
B21: 結構用混凝土，80kgf/cm2 | E21: 110/05/17 | J21: =J19+H21 -> 8 | K21: 組 | M21: 施工廠商:周孝忠
A22: 1-9 | B22: 壹、一、1 結構工程 9、3 排水復舊及臨時導排水工程 9 | C22: =1412+116 -> 1528 | D22: M3 | E22: 110/07/19 | F22: 7 | G22: M3 | H22: =E22 -> 110/07/19 | I22: V=每批數量(M3) V≦50 取樣2(組) 50≦V<100 取樣3組 100≦V<200 取樣4(組) V>200 INT(V/100)+取樣3(組)。 | J22: =J20+F22 -> 156 | K22: M3 | M22: 監造單位:李之杰 | N22: M38A2-J-a-C4A-295 曾文溪河川橋P8L基礎PC
B23: 結構用混凝土，80kgf/cm2 | E23: =E22 -> 110/07/19 | J23: =J21+H23 -> 8 | K23: 組 | M23: 施工廠商:劉琮誠
A24: 1-10 | B24: 壹、一、1 結構工程 9、3 排水復舊及臨時導排水工程 9 | C24: =1412+116 -> 1528 | D24: M3 | E24: 110/08/27 | F24: 30 | G24: M3 | H24: =E24 -> 110/08/27 | I24: V=每批數量(M3) V≦50 取樣2(組) 50≦V<100 取樣3組 100≦V<200 取樣4(組) V>200 INT(V/100)+取樣3(組)。 | J24: =J22+F24 -> 186 | K24: M3 | M24: 監造單位:李之杰 | N24: M38A2-J-a-C4A-324 官田溪河川橋P9R側基礎補強PC
B25: 結構用混凝土，80kgf/cm2 | E25: =E24 -> 110/08/27 | H25: 2 | J25: =J23+H25 -> 10 | K25: 組 | M25: 施工廠商:劉琮誠
A26: 1-11 | B26: 壹、一、1 結構工程 9、3 排水復舊及臨時導排水工程 9 | C26: =1412+116 -> 1528 | D26: M3 | E26: 110/08/30 | F26: 8 | G26: M3 | H26: =E26 -> 110/08/30 | I26: V=每批數量(M3) V≦50 取樣2(組) 50≦V<100 取樣3組 100≦V<200 取樣4(組) V>200 INT(V/100)+取樣3(組)。 | J26: =J24+F26 -> 194 | K26: M3 | M26: 監造單位:吳英傑 | N26: M38A2-J-a-C4A-326 曾文溪河川橋P8R側基礎PC
B27: 結構用混凝土，80kgf/cm2 | E27: =E26 -> 110/08/30 | J27: =J25+H27 -> 10 | K27: 組 | M27: 施工廠商:石錦茹
A28: 1-12 | B28: 壹、一、1 結構工程 9、3 排水復舊及臨時導排水工程 9 | C28: =1412+116 -> 1528 | D28: M3 | E28: 110/09/06 | F28: 20 | G28: M3 | H28: =E28 -> 110/09/06 | I28: V=每批數量(M3) V≦50 取樣2(組) 50≦V<100 取樣3組 100≦V<200 取樣4(組) V>200 INT(V/100)+取樣3(組)。 | J28: =J26+F28 -> 214 | K28: M3 | M28: 監造單位:林東新 | N28: M38A2-J-a-C4A-331 官田溪河川橋P12R側基礎PC
B29: 結構用混凝土，80kgf/cm2 | E29: =E28 -> 110/09/06 | J29: =J27+H29 -> 10 | K29: 組 | M29: 施工廠商:劉琮誠
A30: 1-13 | B30: 壹、一、1 結構工程 9、3 排水復舊及臨時導排水工程 9 | C30: =1412+116 -> 1528 | D30: M3 | E30: 110/09/16 | F30: 31 | G30: M3 | H30: =E30 -> 110/09/16 | I30: V=每批數量(M3) V≦50 取樣2(組) 50≦V<100 取樣3組 100≦V<200 取樣4(組) V>200 INT(V/100)+取樣3(組)。 | J30: =J28+F30 -> 245 | K30: M3 | M30: 監造單位:吳英傑 | N30: M38A2-J-a-C4A-339 官田溪河川橋P16L側基礎PC
B31: 結構用混凝土，80kgf/cm2 | E31: =E30 -> 110/09/16 | H31: 2 | J31: =J29+H31 -> 12 | K31: 組 | M31: 施工廠商:石錦茹
A32: 1-14 | B32: 壹、一、1 結構工程 9、3 排水復舊及臨時導排水工程 9 | C32: =1412+116 -> 1528 | D32: M3 | E32: 110/10/04 | F32: 6 | G32: M3 | H32: =E32 -> 110/10/04 | I32: V=每批數量(M3) V≦50 取樣2(組) 50≦V<100 取樣3組 100≦V<200 取樣4(組) V>200 INT(V/100)+取樣3(組)。 | J32: =J30+F32 -> 251 | K32: M3 | M32: 監造單位:李之杰 | N32: M38A2-J-a-C4A-344 官田系統6號橋P3基礎PC
B33: 結構用混凝土，80kgf/cm2 | E33: =E32 -> 110/10/04 | J33: =J31+H33 -> 12 | K33: 組 | M33: 施工廠商:周孝忠
A34: 1-15 | B34: 壹、一、1 結構工程 9、3 排水復舊及臨時導排水工程 9 | C34: =1412+116 -> 1528 | D34: M3 | E34: 110/10/13 | F34: 16 | G34: M3 | H34: =E34 -> 110/10/13 | I34: V=每批數量(M3) V≦50 取樣2(組) 50≦V<100 取樣3組 100≦V<200 取樣4(組) V>200 INT(V/100)+取樣3(組)。 | J34: =J32+F34 -> 267 | K34: M3 | M34: 監造單位:李秉融 | N34: M38A2-J-a-C4A-361 官田溪河川橋P6L基礎PC
B35: 結構用混凝土，80kgf/cm2 | E35: =E34 -> 110/10/13 | J35: =J33+H35 -> 12 | K35: 組 | M35: 施工廠商:劉琮誠
A36: 1-16 | B36: 壹、一、1 結構工程 9、3 排水復舊及臨時導排水工程 9 | C36: =1412+116 -> 1528 | D36: M3 | E36: 110/11/01 | F36: 8 | G36: M3 | H36: =E36 -> 110/11/01 | I36: V=每批數量(M3) V≦50 取樣2(組) 50≦V<100 取樣3組 100≦V<200 取樣4(組) V>200 INT(V/100)+取樣3(組)。 | J36: =J34+F36 -> 275 | K36: M3 | M36: 監造單位:林東新 | N36: M38A2-J-a-C4A-366 官田五號高架橋P1基礎PC
B37: 結構用混凝土，80kgf/cm2 | E37: =E36 -> 110/11/01 | J37: =J35+H37 -> 12 | K37: 組 | M37: 施工廠商:劉琮誠
A38: 1-17 | B38: 壹、一、1 結構工程 9、3 排水復舊及臨時導排水工程 9 | C38: =1412+116 -> 1528 | D38: M3 | E38: 110/11/03 | F38: 7 | G38: M3 | H38: =E38 -> 110/11/03 | I38: V=每批數量(M3) V≦50 取樣2(組) 50≦V<100 取樣3組 100≦V<200 取樣4(組) V>200 INT(V/100)+取樣3(組)。 | J38: =J36+F38 -> 282 | K38: M3 | M38: 監造單位:李秉融 | N38: M38A2-J-a-C4A-367 南117穿越橋P1R基礎PC
B39: 結構用混凝土，80kgf/cm2 | E39: =E38 -> 110/11/03 | J39: =J37+H39 -> 12 | K39: 組 | M39: 施工廠商:周孝忠
A40: 1-18 | B40: 壹、一、1 結構工程 9、3 排水復舊及臨時導排水工程 9 | C40: =1412+116 -> 1528 | D40: M3 | E40: 110/11/17 | F40: 16 | G40: M3 | H40: =E40 -> 110/11/17 | I40: V=每批數量(M3) V≦50 取樣2(組) 50≦V<100 取樣3組 100≦V<200 取樣4(組) V>200 INT(V/100)+取樣3(組)。 | J40: =J38+F40 -> 298 | K40: M3 | M40: 監造單位:吳英傑 | N40: M38A2-J-a-C4A-380 官田四號高架橋P1基礎PC
...

Sheet 混凝土 80KGF CM3 竑榮官田廠
A1: 國道高速公路後續路段橋梁耐震補強工程(區段2-1)第M38A2標-烏山頭新化段 材料設備檢(試)驗管制總表 製表資料日期:110/02/18止
A2: 項次 | B2: 契約詳細表項次 | C2: 契約數量 | E2: 預定進場日期 | F2: 進場數量 | H2: 抽樣日期 | J2: 規定抽(取)樣頻率 | K2: 累積進場數量 | M2: 抽試驗結果 | N2: 抽驗及會同人員 | O2: 備註
B3: 材料(設備)名稱 | E3: 實際進場日期 | H3: 抽樣數量 | K3: 累積抽樣數量 | O3: (歸檔編號)
A4: 1 | B4: 壹、一、1 結構工程 9、3 排水復舊及臨時導排水工程 9 | C4: =1412+116 -> 1528 | D4: M3 | E4: 109/08/28 | F4: 一式 | G4: M3 | H4: 109/08/28 | J4: V=每批數量(M3) V≦50 取樣2(組) 50≦V<100 取樣3組 100≦V<200 取樣4(組) V>200 INT(V/100)+取樣3(組)。 | K4: 一式 | M4: 合格 | N4: 監造單位:李秉融 | O4: 竑榮官田廠:109.08.14棪嘉南(A2)監字第10908022號函廠商核定。 109.08.25驗廠取樣)。 109.10.06 80、175、245、280、315W廠拌。M38A2-J-a-C1-009 | P4: 1100224
B5: 結構用混凝土，80kgf/cm2 | E5: 109/08/28 | H5: 一式 | K5: 一式 | N5: 施工廠商:柯志龍
A6: 1 | B6: 壹、一、1 結構工程 9、3 排水復舊及臨時導排水工程 9 | C6: =1412+116 -> 1528 | D6: M3 | E6: 109/08/28 | F6: 一式 | G6: M3 | H6: 109/08/28 | J6: V=每批數量(M3) V≦50 取樣2(組) 50≦V<100 取樣3組 100≦V<200 取樣4(組) V>200 INT(V/100)+取樣3(組)。 | K6: 一式 | M6: 合格 | N6: 監造單位:李秉融 | O6: 竑榮安定廠:109.08.14棪嘉南(A2)監字第10908023號函廠商核定。 109.08.31驗廠取樣。 109.10.07 80、175、245、280廠拌。 M38A2-J-a-C1-010
B7: 結構用混凝土，80kgf/cm2 | E7: 109/08/28 | H7: 一式 | K7: 一式 | N7: 施工廠商:柯志龍
A8: 1-1 | B8: 壹、一、1 結構工程 9、3 排水復舊及臨時導排水工程 9 | C8: =1412+116 -> 1528 | D8: M3 | E8: 110/03/31 | F8: 23 | G8: M3 | H8: 110/03/31 | J8: V=每批數量(M3) V≦50 取樣2(組) 50≦V<100 取樣3組 100≦V<200 取樣4(組) V>200 INT(V/100)+取樣3(組)。 | K8: 23 | L8: M3 | M8: 合格 | N8: 監造單位:李之杰 | O8: M38A2-J-a-C4B-104 潭頂溪排水橋P4基礎
B9: 結構用混凝土，80kgf/cm2 | E9: 110/03/31 | H9: 2 | K9: 2 | L9: 組 | N9: 施工廠商:劉琮誠
A10: 1-2 | B10: 壹、一、1 結構工程 9、3 排水復舊及臨時導排水工程 9 | C10: =1412+116 -> 1528 | D10: M3 | E10: 110/06/18 | F10: 3 | G10: M3 | H10: =E10 -> 110/06/18 | J10: V=每批數量(M3) V≦50 取樣2(組) 50≦V<100 取樣3組 100≦V<200 取樣4(組) V>200 INT(V/100)+取樣3(組)。 | K10: =K8+F10 -> 26 | L10: M3 | M10: 合格 | N10: 監造單位:李之杰 | O10: M38A2-J-a-C4B-144 潭頂溪排水橋P6支撐補強PC
B11: 結構用混凝土，80kgf/cm2 | E11: =E10 -> 110/06/18 | I11: 組 | K11: =K9+H11 -> 2 | L11: 組 | N11: 施工廠商:劉琮誠
A12: 1-3 | B12: 壹、一、1 結構工程 9、3 排水復舊及臨時導排水工程 9 | C12: =1412+116 -> 1528 | D12: M3 | E12: 110/07/12 | F12: 55 | G12: M3 | H12: =E12 -> 110/07/12 | J12: V=每批數量(M3) V≦50 取樣2(組) 50≦V<100 取樣3組 100≦V<200 取樣4(組) V>200 INT(V/100)+取樣3(組)。 | K12: =K10+F12 -> 81 | L12: M3 | M12: 合格 | N12: 監造單位:李之杰 | O12: M38A2-J-a-C4B-148 潭頂溪排水橋P3RL基礎補強PC
B13: 結構用混凝土，80kgf/cm2 | E13: =E12 -> 110/07/12 | H13: 3 | I13: 組 | K13: =K11+H13 -> 5 | L13: 組 | N13: 施工廠商:李秉融
A14: 1-4 | B14: 壹、一、1 結構工程 9、3 排水復舊及臨時導排水工程 9 | C14: =1412+116 -> 1528 | D14: M3 | E14: 110/07/27 | F14: 13 | G14: M3 | H14: =E14 -> 110/07/27 | J14: V=每批數量(M3) V≦50 取樣2(組) 50≦V<100 取樣3組 100≦V<200 取樣4(組) V>200 INT(V/100)+取樣3(組)。 | K14: =K12+F14 -> 94 | L14: M3 | M14: 合格 | N14: 監造單位:吳英傑 | O14: M38A2-J-a-C4B-168 潭頂溪排水橋P6RL基礎補強PC
B15: 結構用混凝土，80kgf/cm2 | E15: =E14 -> 110/07/27 | H15: 2 | I15: 組 | K15: =K13+H15 -> 7 | L15: 組 | N15: 施工廠商:石錦茹
A16: 1-5 | B16: 壹、一、1 結構工程 9、3 排水復舊及臨時導排水工程 9 | C16: =1412+116 -> 1528 | D16: M3 | E16: 110/09/24 | F16: 16 | G16: M3 | H16: =E16 -> 110/09/24 | J16: V=每批數量(M3) V≦50 取樣2(組) 50≦V<100 取樣3組 100≦V<200 取樣4(組) V>200 INT(V/100)+取樣3(組)。 | K16: =K14+F16 -> 110 | L16: M3 | M16: 合格 | N16: 監造單位:吳英傑 | O16: M38A2-J-a-C4B-174 潭頂溪排水橋P7RL側基礎底PC
B17: 結構用混凝土，80kgf/cm2 | E17: =E16 -> 110/09/24 | H17: 2 | I17: 組 | K17: =K15+H17 -> 9 | L17: 組 | N17: 施工廠商:石錦茹
A18: 1-6 | B18: 壹、一、1 結構工程 9、3 排水復舊及臨時導排水工程 9 | C18: =1412+116 -> 1528 | D18: M3 | E18: 110/10/25 | F18: 23 | G18: M3 | H18: =E18 -> 110/10/25 | J18: V=每批數量(M3) V≦50 取樣2(組) 50≦V<100 取樣3組 100≦V<200 取樣4(組) V>200 INT(V/100)+取樣3(組)。 | K18: =K16+F18 -> 133 | L18: M3 | M18: 合格 | N18: 監造單位:李之杰 | O18: M38A2-J-a-C4B-178 潭頂溪排水橋P5RL側基礎底PC
B19: 結構用混凝土，80kgf/cm2 | E19: =E18 -> 110/10/25 | I19: 組 | K19: =K17+H19 -> 9 | L19: 組 | N19: 施工廠商:劉琮誠
A20: 1-7 | B20: 壹、一、1 結構工程 9、3 排水復舊及臨時導排水工程 9 | C20: =1412+116 -> 1528 | D20: M3 | E20: 110/11/24 | F20: 24 | G20: M3 | H20: =E20 -> 110/11/24 | J20: V=每批數量(M3) V≦50 取樣2(組) 50≦V<100 取樣3組 100≦V<200 取樣4(組) V>200 INT(V/100)+取樣3(組)。 | K20: =K18+F20 -> 157 | L20: M3 | M20: 合格 | N20: 監造單位:吳英傑 | O20: M38A2-J-a-C4B-185 官田二號高架橋P3基礎PC
B21: 結構用混凝土，80kgf/cm2 | E21: =E20 -> 110/11/24 | H21: 2 | I21: 組 | K21: =K19+H21 -> 11 | L21: 組 | N21: 施工廠商:石錦茹
A22: 1-8 | B22: 壹、一、1 結構工程 9、3 排水復舊及臨時導排水工程 9 | C22: =1412+116 -> 1528 | D22: M3 | E22: 110/11/25 | F22: 4.5 | G22: M3 | H22: =E22 -> 110/11/25 | J22: V=每批數量(M3) V≦50 取樣2(組) 50≦V<100 取樣3組 100≦V<200 取樣4(組) V>200 INT(V/100)+取樣3(組)。 | K22: =K20+F22 -> 161.5 | L22: M3 | M22: 合格 | N22: 監造單位:李之杰 | O22: M38A2-J-a-C4B-186 善化一號排水間穿越橋P2基礎
B23: 結構用混凝土，80kgf/cm2 | E23: =E22 -> 110/11/25 | I23: 組 | K23: =K21+H23 -> 11 | L23: 組 | N23: 施工廠商:劉琮誠
A24: 1-9 | B24: 壹、一、1 結構工程 9、3 排水復舊及臨時導排水工程 9 | C24: =1412+116 -> 1528 | D24: M3 | E24: 110/11/26 | F24: 31 | G24: M3 | H24: =E24 -> 110/11/26 | J24: V=每批數量(M3) V≦50 取樣2(組) 50≦V<100 取樣3組 100≦V<200 取樣4(組) V>200 INT(V/100)+取樣3(組)。 | K24: =K22+F24 -> 192.5 | L24: M3 | M24: 合格 | N24: 監造單位:吳英傑 | O24: M38A2-J-a-C4B-189 官田溪河川橋P16R基礎PC
B25: 結構用混凝土，80kgf/cm2 | E25: =E24 -> 110/11/26 | H25: 2 | I25: 組 | K25: =K23+H25 -> 13 | L25: 組 | N25: 施工廠商:石錦茹
A26: 1-10 | B26: 壹、一、1 結構工程 9、3 排水復舊及臨時導排水工程 9 | C26: =1412+116 -> 1528 | D26: M3 | E26: 110/12/13 | F26: 19 | G26: M3 | H26: =E26 -> 110/12/13 | J26: V=每批數量(M3) V≦50 取樣2(組) 50≦V<100 取樣3組 100≦V<200 取樣4(組) V>200 INT(V/100)+取樣3(組)。 | K26: =K24+F26 -> 211.5 | L26: M3 | M26: 合格 | N26: 監造單位:吳英傑 | O26: M38A2-J-a-C4B-210 官田一號高架橋P5E基礎PC
B27: 結構用混凝土，80kgf/cm2 | E27: =E26 -> 110/12/13 | H27: 2 | I27: 組 | K27: =K25+H27 -> 15 | L27: 組 | N27: 施工廠商:石錦茹
A28: 1-11 | B28: 壹、一、1 結構工程 9、3 排水復舊及臨時導排水工程 9 | C28: =1412+116 -> 1528 | D28: M3 | E28: 110/12/15 | F28: 6 | G28: M3 | H28: =E28 -> 110/12/15 | J28: V=每批數量(M3) V≦50 取樣2(組) 50≦V<100 取樣3組 100≦V<200 取樣4(組) V>200 INT(V/100)+取樣3(組)。 | K28: =K26+F28 -> 217.5 | L28: M3 | M28: 合格 | N28: 監造單位:林東新 | O28: M38A2-J-a-C4B-214 南117穿越橋P2R基礎PC
B29: 結構用混凝土，80kgf/cm2 | E29: =E28 -> 110/12/15 | I29: 組 | K29: =K27+H29 -> 15 | L29: 組 | N29: 施工廠商:劉琮誠
A30: 1-12 | B30: 壹、一、1 結構工程 9、3 排水復舊及臨時導排水工程 9 | C30: =1412+116 -> 1528 | D30: M3 | E30: 110/12/17 | F30: 16 | G30: M3 | H30: =E30 -> 110/12/17 | J30: V=每批數量(M3) V≦50 取樣2(組) 50≦V<100 取樣3組 100≦V<200 取樣4(組) V>200 INT(V/100)+取樣3(組)。 | K30: =K28+F30 -> 233.5 | L30: M3 | M30: 合格 | N30: 監造單位:吳英傑 | O30: M38A2-J-a-C4B-215 官田溪河川橋P7L基礎PC
B31: 結構用混凝土，80kgf/cm2 | E31: =E30 -> 110/12/17 | H31: 2 | I31: 組 | K31: =K29+H31 -> 17 | L31: 組 | N31: 施工廠商:石錦茹
A32: 1-13 | B32: 壹、一、1 結構工程 9、3 排水復舊及臨時導排水工程 9 | C32: =1412+116 -> 1528 | D32: M3 | E32: 110/12/25 | F32: 5.5 | G32: M3 | H32: =E32 -> 110/12/25 | J32: V=每批數量(M3) V≦50 取樣2(組) 50≦V<100 取樣3組 100≦V<200 取樣4(組) V>200 INT(V/100)+取樣3(組)。 | K32: =K30+F32 -> 239 | L32: M3 | M32: 合格 | N32: 監造單位:林東新 | O32: M38A2-J-a-C4B-221 善化一號排水兼穿越橋P1RL基礎PC
B33: 結構用混凝土，80kgf/cm2 | E33: =E32 -> 110/12/25 | H33: 2 | I33: 組 | K33: =K31+H33 -> 19 | L33: 組 | N33: 施工廠商:劉琮誠
A34: 1-14 | B34: 壹、一、1 結構工程 9、3 排水復舊及臨時導排水工程 9 | C34: =1412+116 -> 1528 | D34: M3 | E34: 111/01/03 | F34: 34 | G34: M3 | H34: =E34 -> 111/01/03 | J34: V=每批數量(M3) V≦50 取樣2(組) 50≦V<100 取樣3組 100≦V<200 取樣4(組) V>200 INT(V/100)+取樣3(組)。 | K34: =K32+F34 -> 273 | L34: M3 | M34: 合格 | N34: 監造單位:林東新 | O34: M38A2-J-a-C4B-243 曾文溪橋P9基礎PC
B35: 結構用混凝土，80kgf/cm2 | E35: =E34 -> 111/01/03 | I35: 組 | K35: =K33+H35 -> 19 | L35: 組 | N35: 施工廠商:劉琮誠
A36: 1-15 | B36: 壹、一、1 結構工程 9、3 排水復舊及臨時導排水工程 9 | C36: =1412+116 -> 1528 | D36: M3 | E36: 111/01/08 | F36: 9 | G36: M3 | H36: =E36 -> 111/01/08 | J36: V=每批數量(M3) V≦50 取樣2(組) 50≦V<100 取樣3組 100≦V<200 取樣4(組) V>200 INT(V/100)+取樣3(組)。 | K36: =K34+F36 -> 282 | L36: M3 | M36: 合格 | N36: 監造單位:吳英傑 | O36: M38A2-J-a-C4B-250 官田四號高架橋P7基礎PC
B37: 結構用混凝土，80kgf/cm2 | E37: =E36 -> 111/01/08 | I37: 組 | K37: =K35+H37 -> 19 | L37: 組 | N37: 施工廠商:劉琮誠
A38: 1-16 | B38: 壹、一、1 結構工程 9、3 排水復舊及臨時導排水工程 9 | C38: =1412+116 -> 1528 | D38: M3 | E38: 111/01/18 | F38: 23 | G38: M3 | H38: =E38 -> 111/01/18 | J38: V=每批數量(M3) V≦50 取樣2(組) 50≦V<100 取樣3組 100≦V<200 取樣4(組) V>200 INT(V/100)+取樣3(組)。 | K38: =K36+F38 -> 305 | L38: M3 | M38: 合格 | N38: 監造單位:林東新 | O38: M38A2-J-a-C4B-269 潭頂溪排水橋P2基礎PC
B39: 結構用混凝土，80kgf/cm2 | E39: =E38 -> 111/01/18 | H39: 2 | I39: 組 | K39: =K37+H39 -> 21 | L39: 組 | N39: 施工廠商:劉琮誠
A40: 1-17 | B40: 壹、一、1 結構工程 9、3 排水復舊及臨時導排水工程 9 | C40: =1412+116 -> 1528 | D40: M3 | E40: 111/01/21 | F40: 8 | G40: M3 | H40: =E40 -> 111/01/21 | J40: V=每批數量(M3) V≦50 取樣2(組) 50≦V<100 取樣3組 100≦V<200 取樣4(組) V>200 INT(V/100)+取樣3(組)。 | K40: =K38+F40 -> 313 | L40: M3 | M40: 合格 | N40: 監造單位:林東新 | O40: M38A2-J-a-C4B-273 六雙溪四號排水橋P2基礎PC
...

Sheet 混凝土 245KGF CM3 贊洲
A1: 國道高速公路後續路段橋梁耐震補強工程(區段2-1)第M38A2標-烏山頭新化段 材料設備檢(試)驗管制總表 製表資料日期:110/02/18止
A2: 項次 | B2: 契約詳細表項次 | C2: 契約數量 | E2: 預定進場日期 | F2: 進場數量 | H2: 抽樣日期 | J2: 規定抽(取)樣頻率 | K2: 累積進場數量 | M2: 抽試驗結果 | N2: 抽驗及會同人員 | O2: 備註
B3: 材料(設備)名稱 | E3: 實際進場日期 | H3: 抽樣數量 | K3: 累積抽樣數量 | O3: (歸檔編號)
A4: 2 | B4: 壹、一、3 排水復舊及臨時導排水工程 6 | C4: 1921 | D4: M3 | E4: 109/08/28 | F4: 一式 | G4: M3 | H4: 109/08/28 | J4: V=每批數量(M3) V≦50 取樣2(組) 50≦V<100 取樣3組 100≦V<200 取樣4(組) V>200 INT(V/100)+取樣3(組)。 | K4: 一式 | M4: 合格 | N4: 監造單位:李秉融 | O4: 贊洲:109.07.28棪嘉南(A2)監字第10907060號函廠商核定。 109.07.24 驗廠取樣。 109.08.14 315W廠拌。 109.08.28 80、245、280、350SCC廠拌)。 M38A2-J-a-C1-006。 | P4: 1100224
B5: 結構用混凝土，245kgf/cm2 | E5: 109/08/28 | H5: 一式 | K5: 一式 | N5: 施工廠商:柯志龍
A6: 2-1 | B6: 壹、一、3 排水復舊及臨時導排水工程 6 | C6: 1921 | D6: M3 | E6: 109/09/23 | F6: 88.5 | G6: M3 | H6: 109/09/23 | J6: V=每批數量(M3) V≦50 取樣2(組) 50≦V<100 取樣3組 100≦V<200 取樣4(組) V>200 INT(V/100)+取樣3(組)。 | K6: 88.5 | L6: M3 | M6: 合格 | N6: 監造單位:吳英傑 | O6: M38A2-J-a-C4A-001 官田系統4號高架橋施工便道
B7: 結構用混凝土，245kgf/cm2 | E7: 109/09/23 | H7: 3 | K7: =H7 -> 3 | L7: 組 | N7: 施工廠商:蘇俊男
A8: 2-2 | B8: 壹、一、3 排水復舊及臨時導排水工程 6 | C8: 1921 | D8: M3 | E8: 109/10/15 | F8: 40 | G8: M3 | H8: 109/10/15 | J8: V=每批數量(M3) V≦50 取樣2(組) 50≦V<100 取樣3組 100≦V<200 取樣4(組) V>200 INT(V/100)+取樣3(組)。 | K8: 128.5 | L8: M3 | M8: 合格 | N8: 監造單位:李秉融 | O8: M38A2-J-a-C4A-002 渡子頭二號橋便道
B9: 結構用混凝土，245kgf/cm2 | E9: 109/10/15 | H9: 2 | K9: =K7+H9 -> 5 | L9: 組 | N9: 施工廠商:柯志龍
A10: 2-3 | B10: 壹、一、3 排水復舊及臨時導排水工程 6 | C10: 1921 | D10: M3 | E10: 109/11/28 | F10: 40 | G10: M3 | H10: 109/11/28 | J10: V=每批數量(M3) V≦50 取樣2(組) 50≦V<100 取樣3組 100≦V<200 取樣4(組) V>200 INT(V/100)+取樣3(組)。 | K10: 168.5 | L10: M3 | M10: 合格 | N10: 監造單位:吳英傑 | O10: M38A2-J-a-C4A-049 官田系統4號高架橋施工便道
B11: 結構用混凝土，245kgf/cm2 | E11: 109/11/28 | H11: 2 | K11: =K9+H11 -> 7 | L11: 組 | N11: 施工廠商:蘇俊男
A12: 2-4 | B12: 壹、一、3 排水復舊及臨時導排水工程 6 | C12: 1921 | D12: M3 | E12: 109/11/30 | F12: 48 | G12: M3 | H12: 109/11/30 | J12: V=每批數量(M3) V≦50 取樣2(組) 50≦V<100 取樣3組 100≦V<200 取樣4(組) V>200 INT(V/100)+取樣3(組)。 | K12: 216.5 | L12: M3 | M12: 合格 | N12: 監造單位:吳英傑 | O12: M38A2-J-a-C4A-052 官田系統4號高架橋施工便道
B13: 結構用混凝土，245kgf/cm2 | E13: 109/11/30 | H13: 2 | K13: =K11+H13 -> 9 | L13: 組 | N13: 施工廠商:李秉融
A14: 2-5 | B14: 壹、一、3 排水復舊及臨時導排水工程 6 | C14: 1921 | D14: M3 | E14: 109/12/19 | F14: 41 | G14: M3 | H14: 109/12/19 | J14: V=每批數量(M3) V≦50 取樣2(組) 50≦V<100 取樣3組 100≦V<200 取樣4(組) V>200 INT(V/100)+取樣3(組)。 | K14: 257.5 | L14: M3 | M14: 合格 | N14: 監造單位:吳英傑 | O14: M38A2-J-a-C4A-079 官田溪河川橋P6及P5施工便道
B15: 結構用混凝土，245kgf/cm2 | E15: 109/12/19 | H15: 2 | K15: =K13+H15 -> 11 | L15: 組 | N15: 施工廠商:蘇俊男
A16: 2-6 | B16: 壹、一、3 排水復舊及臨時導排水工程 6 | C16: 1921 | D16: M3 | E16: 109/12/21 | F16: 76 | G16: M3 | H16: 109/12/21 | J16: V=每批數量(M3) V≦50 取樣2(組) 50≦V<100 取樣3組 100≦V<200 取樣4(組) V>200 INT(V/100)+取樣3(組)。 | K16: 333.5 | L16: M3 | M16: 合格 | N16: 監造單位:吳英傑 | O16: M38A2-J-a-C4A-081 官田溪河川橋P6及P5施工便道
B17: 結構用混凝土，245kgf/cm2 | E17: 109/12/21 | H17: 3 | K17: =K15+H17 -> 14 | L17: 組 | N17: 施工廠商:翁瑞祥
A18: 2-7 | B18: 壹、一、3 排水復舊及臨時導排水工程 6 | C18: 1921 | D18: M3 | E18: 109/12/23 | F18: 40 | G18: M3 | H18: 109/12/23 | J18: V=每批數量(M3) V≦50 取樣2(組) 50≦V<100 取樣3組 100≦V<200 取樣4(組) V>200 INT(V/100)+取樣3(組)。 | K18: 373.5 | L18: M3 | M18: 合格 | N18: 監造單位:吳英傑 | O18: M38A2-J-a-C4A-083 官田系統4號高架橋施工便道
B19: 結構用混凝土，245kgf/cm2 | E19: 109/12/23 | H19: 2 | K19: =K17+H19 -> 16 | L19: 組 | N19: 施工廠商:翁瑞祥
A20: 2-8 | B20: 壹、一、3 排水復舊及臨時導排水工程 6 | C20: 1921 | D20: M3 | E20: 109/12/24 | F20: 32 | G20: M3 | H20: 109/12/24 | J20: V=每批數量(M3) V≦50 取樣2(組) 50≦V<100 取樣3組 100≦V<200 取樣4(組) V>200 INT(V/100)+取樣3(組)。 | K20: 405.5 | L20: M3 | M20: 合格 | N20: 監造單位:林東新 | O20: M38A2-J-a-C4A-085 官田系統4號高架橋施工便道
B21: 結構用混凝土，245kgf/cm2 | E21: 109/12/24 | H21: 2 | K21: =K19+H21 -> 18 | L21: 組 | N21: 施工廠商:翁瑞祥
A22: 2-9 | B22: 壹、一、3 排水復舊及臨時導排水工程 6 | C22: 1921 | D22: M3 | E22: 109/12/25 | F22: 16 | G22: M3 | H22: 109/12/25 | J22: V=每批數量(M3) V≦50 取樣2(組) 50≦V<100 取樣3組 100≦V<200 取樣4(組) V>200 INT(V/100)+取樣3(組)。 | K22: 421.5 | L22: M3 | M22: 合格 | N22: 監造單位:李秉融 | O22: M38A2-J-a-C4A-089 官田系統4號高架橋施工便道
B23: 結構用混凝土，245kgf/cm2 | E23: 109/12/25 | H23: 2 | K23: =K21+H23 -> 20 | L23: 組 | N23: 施工廠商:林士興
A24: 2-10 | B24: 壹、一、3 排水復舊及臨時導排水工程 6 | C24: 1921 | D24: M3 | E24: 109/12/28 | F24: 48 | G24: M3 | H24: 109/12/28 | J24: V=每批數量(M3) V≦50 取樣2(組) 50≦V<100 取樣3組 100≦V<200 取樣4(組) V>200 INT(V/100)+取樣3(組)。 | K24: 469.5 | L24: M3 | M24: 合格 | N24: 監造單位:吳英傑 | O24: M38A2-J-a-C4A-092 官田系統4號高架橋施工便道
B25: 結構用混凝土，245kgf/cm2 | E25: 109/12/28 | H25: 2 | K25: =K23+H25 -> 22 | L25: 組 | N25: 施工廠商:林士興
A26: 2-11 | B26: 壹、一、3 排水復舊及臨時導排水工程 6 | C26: 1921 | D26: M3 | E26: 110/01/06 | F26: 24 | G26: M3 | H26: 110/01/06 | J26: V=每批數量(M3) V≦50 取樣2(組) 50≦V<100 取樣3組 100≦V<200 取樣4(組) V>200 INT(V/100)+取樣3(組)。 | K26: 493.5 | L26: M3 | M26: 合格 | N26: 監造單位:李秉融 | O26: M38A2-J-a-C4A-102 官田系統4號高架橋施工便道
B27: 結構用混凝土，245kgf/cm2 | E27: 110/01/06 | H27: 2 | K27: =K25+H27 -> 24 | L27: 組 | N27: 施工廠商:石錦茹
A28: 2-12 | B28: 壹、一、3 排水復舊及臨時導排水工程 6 | C28: 1921 | D28: M3 | E28: 110/02/09 | F28: 124 | G28: M3 | H28: 110/02/09 | J28: V=每批數量(M3) V≦50 取樣2(組) 50≦V<100 取樣3組 100≦V<200 取樣4(組) V>200 INT(V/100)+取樣3(組)。 | K28: 617.5 | L28: M3 | M28: 合格 | N28: 監造單位:吳英傑 | O28: M38A2-J-a-C4A-145 官田系統4號高架橋施工便道
B29: 結構用混凝土，245kgf/cm2 | E29: 110/02/09 | H29: 4 | K29: =K27+H29 -> 28 | L29: 組 | N29: 施工廠商:林士興
A30: 2-13 | B30: 壹、一、3 排水復舊及臨時導排水工程 6 | C30: 1921 | D30: M3 | E30: 110/03/13 | F30: 48 | G30: M3 | H30: 110/03/13 | J30: V=每批數量(M3) V≦50 取樣2(組) 50≦V<100 取樣3組 100≦V<200 取樣4(組) V>200 INT(V/100)+取樣3(組)。 | K30: =K28+F30 -> 665.5 | L30: M3 | M30: 合格 | N30: 監造單位:馮榮泉 | O30: M38A2-J-a-C4A-184 官田系統4號高架橋施工便道
B31: 結構用混凝土，245kgf/cm2 | E31: 110/03/13 | H31: 2 | K31: =K29+H31 -> 30 | L31: 組 | N31: 施工廠商:劉琮誠
A32: 2-14 | B32: 壹、一、3 排水復舊及臨時導排水工程 6 | C32: 1921 | D32: M3 | E32: 110/08/12 | F32: 56 | G32: M3 | H32: =E32 -> 110/08/12 | J32: V=每批數量(M3) V≦50 取樣2(組) 50≦V<100 取樣3組 100≦V<200 取樣4(組) V>200 INT(V/100)+取樣3(組)。 | K32: =K30+F32 -> 721.5 | L32: M3 | M32: 合格 | N32: 監造單位:吳英傑 | O32: M38A2-J-a-C4A-307 官田系統三號橋施工便道
B33: 結構用混凝土，245kgf/cm2 | E33: =E32 -> 110/08/12 | H33: 3 | K33: =K31+H33 -> 33 | L33: 組 | N33: 施工廠商:石錦茹
A34: 2-15 | B34: 壹、一、3 排水復舊及臨時導排水工程 6 | C34: 1921 | D34: M3 | E34: 110/09/13 | F34: 40 | G34: M3 | H34: =E34 -> 110/09/13 | J34: V=每批數量(M3) V≦50 取樣2(組) 50≦V<100 取樣3組 100≦V<200 取樣4(組) V>200 INT(V/100)+取樣3(組)。 | K34: =K32+F34 -> 761.5 | L34: M3 | M34: 合格 | N34: 監造單位:吳英傑 | O34: M38A2-J-a-C4A-336 官田系統一號橋施工便道
B35: 結構用混凝土，245kgf/cm2 | E35: =E34 -> 110/09/13 | H35: 2 | K35: =K33+H35 -> 35 | L35: 組 | N35: 施工廠商:石錦茹
A36: 2-16 | B36: 壹、一、3 排水復舊及臨時導排水工程 6 | C36: 1921 | D36: M3 | E36: 111/03/14 | F36: 20 | G36: M3 | H36: =E36 -> 111/03/14 | J36: V=每批數量(M3) V≦50 取樣2(組) 50≦V<100 取樣3組 100≦V<200 取樣4(組) V>200 INT(V/100)+取樣3(組)。 | K36: =K34+F36 -> 781.5 | L36: M3 | M36: 合格 | N36: 監造單位:李秉融 | O36: M38A2-J-a-C4A-402 官田溪河川橋P20L基礎PC
B37: 結構用混凝土，245kgf/cm2 | E37: =E36 -> 111/03/14 | H37: 2 | K37: =K35+H37 -> 37 | L37: 組 | N37: 施工廠商:周孝忠
A38: 2-17 | B38: 壹、一、3 排水復舊及臨時導排水工程 6 | C38: 1921 | D38: M3 | E38: 111/03/24 | F38: 14 | G38: M3 | H38: =E38 -> 111/03/24 | J38: V=每批數量(M3) V≦50 取樣2(組) 50≦V<100 取樣3組 100≦V<200 取樣4(組) V>200 INT(V/100)+取樣3(組)。 | K38: =K36+F38 -> 795.5 | L38: M3 | M38: 合格 | N38: 監造單位:吳英傑 | O38: M38A2-J-a-C4A-405 官田系統洗車台
B39: 結構用混凝土，245kgf/cm2 | E39: =E38 -> 111/03/24 | H39: 2 | K39: =K37+H39 -> 39 | L39: 組 | N39: 施工廠商:石錦茹
A40: 2-18 | B40: 壹、一、3 排水復舊及臨時導排水工程 6 | C40: 1921 | D40: M3 | E40: 111/04/01 | F40: 16 | G40: M3 | H40: =E40 -> 111/04/01 | J40: V=每批數量(M3) V≦50 取樣2(組) 50≦V<100 取樣3組 100≦V<200 取樣4(組) V>200 INT(V/100)+取樣3(組)。 | K40: =K38+F40 -> 811.5 | L40: M3 | M40: 合格 | N40: 監造單位:吳英傑 | O40: M38A2-J-a-C4A-411 官田系統一號橋施工便道
...

Sheet 混凝土 245KGF CM3 竑榮官田廠
A1: 國道高速公路後續路段橋梁耐震補強工程(區段2-1)第M38A2標-烏山頭新化段 材料設備檢(試)驗管制總表 製表資料日期:110/02/18止
A2: 項次 | B2: 契約詳細表項次 | C2: 契約數量 | E2: 預定進場日期 | F2: 進場數量 | H2: 抽樣日期 | J2: 規定抽(取)樣頻率 | K2: 累積進場數量 | M2: 抽試驗結果 | N2: 抽驗及會同人員 | O2: 備註
B3: 材料(設備)名稱 | E3: 實際進場日期 | H3: 抽樣數量 | K3: 累積抽樣數量 | O3: (歸檔編號)
A4: 2 | B4: 壹、一、3 排水復舊及臨時導排水工程 6 | C4: 1921 | D4: M3 | E4: 109/08/28 | F4: 一式 | G4: M3 | H4: 109/08/28 | J4: V=每批數量(M3) V≦50 取樣2(組) 50≦V<100 取樣3組 100≦V<200 取樣4(組) V>200 INT(V/100)+取樣3(組)。 | K4: 一式 | M4: 合格 | N4: 監造單位:李秉融 | O4: 竑榮官田廠:109.08.14棪嘉南(A2)監字第10908022號函廠商核定。 109.08.25驗廠取樣)。 109.10.06 80、175、245、280、315W廠拌。M38A2-J-a-C1-009
B5: 結構用混凝土，245kgf/cm2 | E5: 109/08/28 | H5: 一式 | K5: 一式 | N5: 施工廠商:柯志龍
A6: 2 | B6: 壹、一、3 排水復舊及臨時導排水工程 6 | C6: 1921 | D6: M3 | E6: 109/08/28 | F6: 一式 | G6: M3 | H6: 109/08/28 | J6: V=每批數量(M3) V≦50 取樣2(組) 50≦V<100 取樣3組 100≦V<200 取樣4(組) V>200 INT(V/100)+取樣3(組)。 | K6: 一式 | M6: 合格 | N6: 監造單位:李秉融 | O6: 竑榮安定廠:109.08.14棪嘉南(A2)監字第10908023號函廠商核定。 109.08.31驗廠取樣。 109.10.07 80、175、245、280廠拌。 M38A2-J-a-C1-010
B7: 結構用混凝土，245kgf/cm2 | E7: 109/08/28 | H7: 一式 | K7: 一式 | N7: 施工廠商:柯志龍
A8: 2-1 | B8: 壹、一、3 排水復舊及臨時導排水工程 6 | C8: 1921 | D8: M3 | E8: 109/12/17 | F8: 23 | G8: M3 | H8: 109/12/17 | J8: V=每批數量(M3) V≦50 取樣2(組) 50≦V<100 取樣3組 100≦V<200 取樣4(組) V>200 INT(V/100)+取樣3(組)。 | K8: 23 | L8: M3 | M8: 合格 | N8: 監造單位:林東新 | O8: M38A2-J-a-C4B-015 潭頂溪排水橋洗車台及施工便道
B9: 結構用混凝土，245kgf/cm2 | E9: 109/12/17 | H9: 2 | I9: 組 | K9: 2 | L9: 組 | N9: 施工廠商:翁瑞祥
A10: 2-2 | B10: 壹、一、3 排水復舊及臨時導排水工程 6 | C10: 1921 | D10: M3 | E10: 110/06/08 | F10: 4 | G10: M3 | H10: 110/06/08 | J10: V=每批數量(M3) V≦50 取樣2(組) 50≦V<100 取樣3組 100≦V<200 取樣4(組) V>200 INT(V/100)+取樣3(組)。 | K10: =K8+F10 -> 27 | L10: M3 | M10: 合格 | N10: 監造單位:吳英傑 | O10: M38A2-J-a-C4B-134 曾文溪河川橋人員休息區地坪(P12L旁)
B11: 結構用混凝土，245kgf/cm2 | E11: 110/06/08 | H11: 2 | I11: 組 | K11: =K9+H11 -> 4 | L11: 組 | N11: 施工廠商:石錦茹
A12: 2-3 | B12: 壹、一、3 排水復舊及臨時導排水工程 6 | C12: 1921 | D12: M3 | E12: 110/09/10 | F12: 73.5 | G12: M3 | H12: =E12 -> 110/09/10 | J12: V=每批數量(M3) V≦50 取樣2(組) 50≦V<100 取樣3組 100≦V<200 取樣4(組) V>200 INT(V/100)+取樣3(組)。 | K12: =K10+F12 -> 100.5 | L12: M3 | M12: 合格 | N12: 監造單位:李之杰 | O12: M38A2-J-a-C4B-173 官田系統南下側交維系統施工便道及官田系統一號高架橋施工便道
B13: 結構用混凝土，245kgf/cm2 | E13: =E12 -> 110/09/10 | H13: 3 | I13: 組 | K13: =K11+H13 -> 7 | L13: 組 | N13: 施工廠商:周孝忠
A14: 2-4 | B14: 壹、一、3 排水復舊及臨時導排水工程 6 | C14: 1921 | D14: M3 | E14: 110/11/23 | F14: 64 | G14: M3 | H14: =E14 -> 110/11/23 | J14: V=每批數量(M3) V≦50 取樣2(組) 50≦V<100 取樣3組 100≦V<200 取樣4(組) V>200 INT(V/100)+取樣3(組)。 | K14: =K12+F14 -> 164.5 | L14: M3 | M14: 合格 | N14: 監造單位:李之杰 | O14: M38A2-J-a-C4B-183 官田系統主線便道
B15: 結構用混凝土，245kgf/cm2 | E15: =E14 -> 110/11/23 | H15: 3 | I15: 組 | K15: =K13+H15 -> 10 | L15: 組 | N15: 施工廠商:石錦茹
A16: 2-5 | B16: 壹、一、3 排水復舊及臨時導排水工程 6 | C16: 1921 | D16: M3 | E16: 110/11/24 | F16: 16 | G16: M3 | H16: =E16 -> 110/11/24 | J16: V=每批數量(M3) V≦50 取樣2(組) 50≦V<100 取樣3組 100≦V<200 取樣4(組) V>200 INT(V/100)+取樣3(組)。 | K16: =K14+F16 -> 180.5 | L16: M3 | M16: 合格 | N16: 監造單位:吳英傑 | O16: M38A2-J-a-C4B-184 官田系統主線便道
B17: 結構用混凝土，245kgf/cm2 | E17: =E16 -> 110/11/24 | H17: 2 | I17: 組 | K17: =K15+H17 -> 12 | L17: 組 | N17: 施工廠商:石錦茹
A18: 2-6 | B18: 壹、一、3 排水復舊及臨時導排水工程 6 | C18: 1921 | D18: M3 | E18: 111/02/17 | F18: 107 | G18: M3 | H18: =E18 -> 111/02/17 | J18: V=每批數量(M3) V≦50 取樣2(組) 50≦V<100 取樣3組 100≦V<200 取樣4(組) V>200 INT(V/100)+取樣3(組)。 | K18: =K16+F18 -> 287.5 | L18: M3 | M18: 合格 | N18: 監造單位:吳英傑 | O18: M38A2-J-a-C4B-302 曾文溪橋10噸鼎塊01~24
B19: 結構用混凝土，245kgf/cm2 | E19: =E18 -> 111/02/17 | H19: 4 | I19: 組 | K19: =K17+H19 -> 16 | L19: 組 | N19: 施工廠商:石錦茹
A20: 2-7 | B20: 壹、一、3 排水復舊及臨時導排水工程 6 | C20: 1921 | D20: M3 | E20: 111/02/19 | F20: 107 | G20: M3 | H20: =E20 -> 111/02/19 | J20: V=每批數量(M3) V≦50 取樣2(組) 50≦V<100 取樣3組 100≦V<200 取樣4(組) V>200 INT(V/100)+取樣3(組)。 | K20: =K18+F20 -> 394.5 | L20: M3 | M20: 合格 | N20: 監造單位:吳英傑 | O20: M38A2-J-a-C4B-303 曾文溪橋10噸鼎塊25~48
B21: 結構用混凝土，245kgf/cm2 | E21: =E20 -> 111/02/19 | H21: 4 | I21: 組 | K21: =K19+H21 -> 20 | L21: 組 | N21: 施工廠商:石錦茹
A22: 2-8 | B22: 壹、一、3 排水復舊及臨時導排水工程 6 | C22: 1921 | D22: M3 | E22: 111/02/22 | F22: 46 | G22: M3 | H22: =E22 -> 111/02/22 | J22: V=每批數量(M3) V≦50 取樣2(組) 50≦V<100 取樣3組 100≦V<200 取樣4(組) V>200 INT(V/100)+取樣3(組)。 | K22: =K20+F22 -> 440.5 | L22: M3 | M22: 合格 | N22: 監造單位:吳英傑 | O22: M38A2-J-a-C4B-311 171甲穿越橋P2RL基礎PC
B23: 結構用混凝土，245kgf/cm2 | E23: =E22 -> 111/02/22 | H23: 2 | I23: 組 | K23: =K21+H23 -> 22 | L23: 組 | N23: 施工廠商:石錦茹
A24: 2-9 | B24: 壹、一、3 排水復舊及臨時導排水工程 6 | C24: 1921 | D24: M3 | E24: 111/02/23 | F24: 107 | G24: M3 | H24: =E24 -> 111/02/23 | J24: V=每批數量(M3) V≦50 取樣2(組) 50≦V<100 取樣3組 100≦V<200 取樣4(組) V>200 INT(V/100)+取樣3(組)。 | K24: =K22+F24 -> 547.5 | L24: M3 | M24: 合格 | N24: 監造單位:李秉融 | O24: M38A2-J-a-C4B-312 曾文溪橋10噸鼎塊49~72
B25: 結構用混凝土，245kgf/cm2 | E25: =E24 -> 111/02/23 | H25: 4 | I25: 組 | K25: =K23+H25 -> 26 | L25: 組 | N25: 施工廠商:劉琮誠
A26: 2-10 | B26: 壹、一、3 排水復舊及臨時導排水工程 6 | C26: 1921 | D26: M3 | E26: 111/02/24 | F26: 107 | G26: M3 | H26: =E26 -> 111/02/24 | J26: V=每批數量(M3) V≦50 取樣2(組) 50≦V<100 取樣3組 100≦V<200 取樣4(組) V>200 INT(V/100)+取樣3(組)。 | K26: =K24+F26 -> 654.5 | L26: M3 | M26: 合格 | N26: 監造單位:吳英傑 | O26: M38A2-J-a-C4B-314 曾文溪橋10噸鼎塊73-96
B27: 結構用混凝土，245kgf/cm2 | E27: =E26 -> 111/02/24 | H27: 4 | I27: 組 | K27: =K25+H27 -> 30 | L27: 組 | N27: 施工廠商:石錦茹
A28: 2-11 | B28: 壹、一、3 排水復舊及臨時導排水工程 6 | C28: 1921 | D28: M3 | E28: 111/02/25 | F28: 107 | G28: M3 | H28: =E28 -> 111/02/25 | J28: V=每批數量(M3) V≦50 取樣2(組) 50≦V<100 取樣3組 100≦V<200 取樣4(組) V>200 INT(V/100)+取樣3(組)。 | K28: =K26+F28 -> 761.5 | L28: M3 | M28: 合格 | N28: 監造單位:吳英傑 | O28: M38A2-J-a-C4B-315 曾文溪橋10噸鼎塊97-120
B29: 結構用混凝土，245kgf/cm2 | E29: =E28 -> 111/02/25 | H29: 4 | I29: 組 | K29: =K27+H29 -> 34 | L29: 組 | N29: 施工廠商:石錦茹
A30: 2-12 | B30: 壹、一、3 排水復舊及臨時導排水工程 6 | C30: 1921 | D30: M3 | E30: 111/02/26 | F30: 107 | G30: M3 | H30: =E30 -> 111/02/26 | J30: V=每批數量(M3) V≦50 取樣2(組) 50≦V<100 取樣3組 100≦V<200 取樣4(組) V>200 INT(V/100)+取樣3(組)。 | K30: =K28+F30 -> 868.5 | L30: M3 | M30: 合格 | N30: 監造單位:李秉融 | O30: M38A2-J-a-C4B-322 曾文溪橋10噸鼎塊121-144
B31: 結構用混凝土，245kgf/cm2 | E31: =E30 -> 111/02/26 | H31: 4 | I31: 組 | K31: =K29+H31 -> 38 | L31: 組 | N31: 施工廠商:劉琮誠
A32: 2-13 | B32: 壹、一、3 排水復舊及臨時導排水工程 6 | C32: 1921 | D32: M3 | E32: 111/03/01 | F32: 107 | G32: M3 | H32: =E32 -> 111/03/01 | J32: V=每批數量(M3) V≦50 取樣2(組) 50≦V<100 取樣3組 100≦V<200 取樣4(組) V>200 INT(V/100)+取樣3(組)。 | K32: =K30+F32 -> 975.5 | L32: M3 | M32: 合格 | N32: 監造單位:吳英傑 | O32: M38A2-J-a-C4B-324 曾文溪橋10噸鼎塊145-168
B33: 結構用混凝土，245kgf/cm2 | E33: =E32 -> 111/03/01 | H33: 4 | I33: 組 | K33: =K31+H33 -> 42 | L33: 組 | N33: 施工廠商:石錦茹
A34: 2-14 | B34: 壹、一、3 排水復舊及臨時導排水工程 6 | C34: 1921 | D34: M3 | E34: 111/03/02 | F34: 107 | G34: M3 | H34: =E34 -> 111/03/02 | J34: V=每批數量(M3) V≦50 取樣2(組) 50≦V<100 取樣3組 100≦V<200 取樣4(組) V>200 INT(V/100)+取樣3(組)。 | K34: =K32+F34 -> 1082.5 | L34: M3 | M34: 合格 | N34: 監造單位:吳英傑 | O34: M38A2-J-a-C4B-331 曾文溪橋10噸鼎塊169-192
B35: 結構用混凝土，245kgf/cm2 | E35: =E34 -> 111/03/02 | H35: 4 | I35: 組 | K35: =K33+H35 -> 46 | L35: 組 | N35: 施工廠商:石錦茹
A36: 2-15 | B36: 壹、一、3 排水復舊及臨時導排水工程 6 | C36: 1921 | D36: M3 | E36: 111/03/02 | F36: 7 | G36: M3 | H36: =E36 -> 111/03/02 | J36: V=每批數量(M3) V≦50 取樣2(組) 50≦V<100 取樣3組 100≦V<200 取樣4(組) V>200 INT(V/100)+取樣3(組)。 | K36: =K34+F36 -> 1089.5 | L36: M3 | M36: 合格 | N36: 監造單位:吳英傑 | O36: M38A2-J-a-C4B-332 南117穿越橋P2L基礎PC
B37: 結構用混凝土，245kgf/cm2 | E37: =E36 -> 111/03/02 | H37: 2 | I37: 組 | K37: =K35+H37 -> 48 | L37: 組 | N37: 施工廠商:石錦茹
A38: 2-16 | B38: 壹、一、3 排水復舊及臨時導排水工程 6 | C38: 1921 | D38: M3 | E38: 111/03/03 | F38: 107 | G38: M3 | H38: =E38 -> 111/03/03 | J38: V=每批數量(M3) V≦50 取樣2(組) 50≦V<100 取樣3組 100≦V<200 取樣4(組) V>200 INT(V/100)+取樣3(組)。 | K38: =K36+F38 -> 1196.5 | L38: M3 | M38: 合格 | N38: 監造單位:李秉融 | O38: M38A2-J-a-C4B-333 曾文溪橋10噸鼎塊193-216
B39: 結構用混凝土，245kgf/cm2 | E39: =E38 -> 111/03/03 | H39: 4 | I39: 組 | K39: =K37+H39 -> 52 | L39: 組 | N39: 施工廠商:劉琮誠
A40: 2-17 | B40: 壹、一、3 排水復舊及臨時導排水工程 6 | C40: 1921 | D40: M3 | E40: 111/03/04 | F40: 107 | G40: M3 | H40: =E40 -> 111/03/04 | J40: V=每批數量(M3) V≦50 取樣2(組) 50≦V<100 取樣3組 100≦V<200 取樣4(組) V>200 INT(V/100)+取樣3(組)。 | K40: =K38+F40 -> 1303.5 | L40: M3 | M40: 合格 | N40: 監造單位:李秉融 | O40: M38A2-J-a-C4B-334 曾文溪橋10噸鼎塊217-240
...

Sheet 混凝土 280KGF CM3 贊洲 
A1: 國道高速公路後續路段橋梁耐震補強工程(區段2-1)第M38A2標-烏山頭新化段 材料設備檢(試)驗管制總表 製表資料日期:110/02/18止
A2: 項次 | B2: 契約詳細表項次 | C2: 契約數量 | E2: 預定進場日期 | F2: 進場數量 | H2: 抽樣日期 | J2: 規定抽(取)樣頻率 | K2: 累積進場數量 | M2: 抽試驗結果 | N2: 抽驗及會同人員 | O2: 備註
B3: 材料(設備)名稱 | E3: 實際進場日期 | H3: 抽樣數量 | K3: 累積抽樣數量 | O3: (歸檔編號)
A4: 3 | B4: 壹、一、1 結構工程 10、11 | C4: 5405 | D4: M3 | E4: 109/08/14 | F4: 一式 | G4: M3 | H4: 一式 | J4: V=每批數量(M3) V≦50 取樣2(組) 50≦V<100 取樣3組 100≦V<200 取樣4(組) V>200 INT(V/100)+取樣3(組)。 | K4: 一式 | M4: 合格 | N4: 監造單位:李秉融 | O4: 贊洲:109.07.28棪嘉南(A2)監字第10907060號函廠商核定。 109.07.24 驗廠取樣。 109.08.14 315W廠拌。 109.08.28 80、245、280、350SCC廠拌)。 M38A2-J-a-C1-006。 | P4: 1100224
